Workbook

Sheet Totals
A1: # Queries Single Object | B1: =COUNTA('Single Object'!1:1) - 5
A2: # Queries Block | B2: =COUNTA(Block!1:1) - 5
A3: # Queries Segmented | B3: =COUNTA('Segmented & Graft'!1:1) -5
A4: # Queries Star | B4: =COUNTA('Star & H-polymer'!1:1) -5
A5: # Queries Network | B5: =COUNTA('Dendrimer & Network'!1:1) -5
A6: # Queries Ladder | B6: =COUNTA(Ladder!1:1) -5
A7: Total Queries | B7: =SUM(B1:B6)
A8: # Targets | B8: =COUNTA('Single Object'!A:A) - 1
A9: Total | B9: =B7*B8

Sheet Single Object
A1: Targets (BigSMILES) | B1: Single Object Canonicalized | C1: Name | D1: Source | E1: Queries (BigSMILES) | F1: {[][<]CCO[>][]} | G1: {[][<]OCC[>][]} | H1: {[][<2]CCO[>2][]} | I1: {[][>]CCO[<][]} | J1: {[][>]CCO[<],[>]CCO[<][]} | K1: {[][$]CCO[$][]} | L1: {[][<]COC[>][]} | M1: {[][$]COC[$][]} | N1: {[][$]COC[$],[$]COC[$][]} | O1: O{[>][<]CCO[>][<]}CCO | P1: O{[>][>]OCC[<][<]}CCO | Q1: O{[>][>]OCC[<],[>]OCC[<][<]}CCO | R1: OC{[>][<]COC[>][<]}CO | S1: OC{[>][<]CO[<2],[>2]C[>][<]}CO | T1: OC{[>][<]C[<3],[>3]O[<2],[>2]C[>][<]}CO | U1: OCC{[>][<]OCC[>][<]}O | V1: {[>][<]CCO[>][<]} | W1: {[>][<]OCC[>][<]} | X1: {[>][<]CC(O[>])[<]} | Y1: {[>][<]C[<2],[>2]CO[>][<]} | Z1: {[>][>2]CO[>],[<]C[<2][<]} | AA1: {[>][<]CC[>3],[<3]O[>][<]} | AB1: {[>][<]CCO[>],[<]CCO[>][<]} | AC1: N#CC(C)(C){[$][$]CC(c1ccccc1)[$];[$]C(C)(C)C#N,[$]C=C(c1ccccc1)[]} | AD1: N#CC(C)(C){[$][$]CC(c1ccccc1)[$];[$]C=C(c1ccccc1),[$]C(C)(C)C#N[]} | AE1: N#CC(C)(C){[$][$]CC(c1ccccc1)[$],[$]CC(c1ccccc1)[$];[$]C=C(c1ccccc1),[$]C(C)(C)C#N[]} | AF1: N#CC(C)({[$][$]CC(c5ccccc5)[$];[$]C(C)(C)(C#N),[$]C=C(c1ccccc1)[]})C | AG1: N#CC(C)(C){[$][$]C[<2],[>2]C(c1ccccc1)[$];[$]C(C)(C)C#N,[$]C=C(c1ccccc1)[]} | AH1: C[Si](C)(C)O[Si](C)(C)O{[>][<][Si](C)(C)O[>][<]}[Si](C)(C)C | AI1: C[Si](C)(C)O[Si](C)(C)O{[>][<][Si](C)(C)O[>],[<][Si](C)(C)O[>][<]}[Si](C)(C)C | AJ1: C[Si](C)(C)O[Si](C)(C)O{[>][<][Si](C)(C)[>2],[<2]O[>][<]}[Si](C)(C)C | AK1: C[Si](C)(C)O[Si](C)(C){[>][<]O[Si](C)(C)[>][<]}O[Si](C)(C)C | AL1: C[Si](C)(C)O{[>][<][Si](C)(C)O[>][<]}[Si](C)(C)O[Si](C)(C)C | AM1: {[][$]CC(c1ccccc1)[$][]} | AN1: {[][$]CC(c2ccccc2)[$][]} | AO1: {[][$]CC(c1ccccc1)[$],[$]C(c1ccccc1)C[$][]} | AP1: {[][$]C(c1ccccc1)C[$][]} | AQ1: {[][$]CC(c1ccccc1)[$],[$]CC(c1ccccc1)[$][]} | AR1: {[][$]CC([$])c1ccccc1[]} | AS1: {[][$2]CC(c1ccccc1)[$2][]} | AT1: {[][<]CC(c1ccccc1)[>],[<]C(c1ccccc1)C[>][]} | AU1: {[][<]CC(c1ccccc1)[>],[<]C(c1ccccc1)C[>],[<]C(c1ccccc1)C[>][]} | AV1: {[][$]CC[$][]} | AW1: {[][$2]CC[$2][]} | AX1: {[][$]CC[$],[$]CC[$][]} | AY1: {[][<]CC[>][]} | AZ1: {[][<]C(C[>])[]} | BA1: {[][<]CC(Cl)C(Cl)C[>][]} | BB1: {[][<]CC(Cl)C(Cl)C[>],[<]CC(Cl)C(Cl)C[>][]} | BC1: {[][$]CC(Cl)C(Cl)C[$][]} | BD1: {[][$]CC(Cl)C(Cl)C[$],[$]CC(Cl)C(Cl)C[$][]} | BE1: O{[>][<]C(=O)C(C)N[>],[<]C(=O)CN[>][<]} | BF1: O{[>2][<2]C(=O)C(C)N[>2],[<2]C(=O)CN[>2][<2]} | BG1: O{[>][<]C(=O)[<2],[>2]C(C)N[>],[<]C(=O)CN[>][<]} | BH1: O{[>][<]C(=O)CN[>],[<]C(=O)C(C)N[>][<]} | BI1: O{[>][<]C(=O)C(C)N[>],[<]C(=O)CN[>],[<]C(=O)CN[>][<]} | BJ1: {[<][<]C(=O)C(C)N[>],[<]C(=O)CN[>][>]}O | BK1: {[>][<]C(=O)C(C)N[>],[<]C(=O)CN[>][>]}O | BL1: C(c1ccccc1)O{[>][<]CCO[>],[<]CC(COCCN(C(C)C)(C(C)C))O[>][<]}[H] | BM1: C(c1ccccc1)O{[>][<]C[<2],[>2]CO[>],[<]CC(COCCN(C(C)C)(C(C)C))O[>][<]}[H] | BN1: C(c1ccccc1)O{[>][<]CC(COCCN(C(C)C)(C(C)C))O[>],[<]CCO[>][<]}[H] | BO1: {[][<]CCO[>],[<]CC(COCCN(C(C)C)(C(C)C))O[>];[>]OC(c1ccccc1)[<]}[H] | BP1: O{[$][$]CC(c1ccccc1)[$],[$]CC(C)(C(=O)OC)[$][$]}ON1C(C)(C)CCCC1(C)(C) | BQ1: O{[$][$]CC(C)(C(=O)OC)[$],[$]CC(c1ccccc1)[$][$]}ON1C(C)(C)CCCC1(C)(C) | BR1: O{[$][$]C[<2],[>2]C(C)(C(=O)OC)[$],[$]CC(c1ccccc1)[$][$]}ON1C(C)(C)CCCC1(C)(C) | BS1: O{[$][$]C[<2],[>2]C(C)(C(=O)OC)[$],[$]C[<3],[>3]C(c1ccccc1)[$][$]}ON1C(C)(C)CCCC1(C)(C) | BT1: O{[$][$]CC(c1ccccc1)[$],[$]CC(C)(C(=O)OC)[$],[$]CC(C)(C(=O)OC)[$][$]}ON1C(C)(C)CCCC1(C)(C) | BU1: {[][$]CC=C(CCC)C[$][]} | BV1: {[][$2]CC=C(CCC)C[$2][]} | BW1: {[][$]CC=C(CCC)C[$][$]}CC=C(CCC)C | BX1: {[][<]CC=C(CCC)C[>],[<]CC(CCC)=CC[>][]} | BY1: {[][$]CC=C(C[$])CCC[]} | BZ1: {[][<]C\C=C/C[>][]} | CA1: {[][<]C/C=C\C[>][]} | CB1: {[][$]C\C=C/C[$][]} | CC1: {[][$]C\C=C/C[$],[$]C\C=C/C[$][]} | CD1: {[][<]C(C(F)(F)F)OC(F)(F)C(F)(F)C(F)(F)C(F)(F)C(F)(F)OC(F)(C(F)(F)F)c1nc(nc(C)n1)[>][]} | CE1: {[][>]C(C(F)(F)F)OC(F)(F)C(F)(F)C(F)(F)C(F)(F)C(F)(F)OC(F)(C(F)(F)F)c1nc(nc(C)n1)[<][]} | CF1: {[][<]C(C(F)(F)F)OC(F)(F)C(F)(F)C(F)(F)C(F)(F)C(F)(F)OC(F)(C(F)(F)F)c1nc(nc(C)n1)[>],[<]C(C(F)(F)F)OC(F)(F)C(F)(F)C(F)(F)C(F)(F)C(F)(F)OC(F)(C(F)(F)F)c1nc(nc(C)n1)[>][]} | CG1: {[][<]OCCO[<],[>]C(=O)CCC(=O)[>][]} | CH1: {[][<]OCCOC(=O)CCC(=O)[>][]} | CI1: {[][>]C(=O)CCC(=O)[>],[<]OCCO[<][]} | CJ1: {[][<]C(=O)CCC(=O)OCCO[>][]} | CK1: {[][<]OCCO[<],[>]C(=O)CCC(=O)[>],[>]C(=O)CCC(=O)[>][]} | CL1: {[][<]OCCO[<],[>]C(=O)c1cccc2c1cccc2C(=O)[>][]} | CM1: {[][>]C(=O)c1cccc2c1cccc2C(=O)[>],[<]OCCO[<],[>]C(=O)c1cccc2c1cccc2C(=O)[>][]} | CN1: {[][<]OCCO[<],[>]C(=O)c1cccc2c1cccc2C(=O)[>],[<]OCCO[<],[>]C(=O)c1cccc2c1cccc2C(=O)[>][]} | CO1: {[][<]OCCOC(=O)c1cccc2c1cccc2C(=O)[>][]} | CP1: {[][>]C(=O)c1cccc2c1cccc2C(=O)[>],[<]OCCO[<][]} | CQ1: {[][$]Cc1c(Cl)cc(cc1)C[$][]} | CR1: {[][$]Cc1c(Cl)cc(C[$])cc1[]} | CS1: {[][$]Cc2c(Cl)cc(cc2)C[$][]} | CT1: {[][$2]Cc1c(Cl)cc(cc1)C[$2][]} | CU1: {[][$]Cc1c(Cl)cc(cc1)C[$],[$]Cc1c(Cl)cc(cc1)C[$][]} | CV1: C{[<][>]OCC[<][>]}OC(=O)C=C | CW1: C{[<][>]O[<2],[>2]CC[<][>]}OC(=O)C=C | CX1: C{[<][>2]CC[<],[>]O[<2][>]}OC(=O)C=C | CY1: C=CC(=O)O{[>][>]OCC[<][<]}C | CZ1: C{[<][<]CCO[>][>]}OC(=O)C=C | DA1: C{[<][>]OCC[<],[>]OCC[<][>]}OC(=O)C=C | DB1: C{[<][>]OCC[<];[>]OC(=O)C=C[]} | DC1: {[][$]CC(c1c(Cl)c(Cl)c(Cl)cc1)[$],[$]CC(c1c(Cl)c(Cl)cc(Cl)c1)[$],[$]CC(c1c(Cl)c(Cl)ccc1(Cl))[$],[$]CC(c1cc(Cl)c(Cl)c(Cl)c1)[$],[$]CC(c1c(Cl)cc(Cl)cc1(Cl))[$][]} | DD1: {[][$]CC(c1c(Cl)c(Cl)c(Cl)cc1)[$],[$]CC(c1c(Cl)c(Cl)cc(Cl)c1)[$],[$]CC(c1c(Cl)c(Cl)ccc1(Cl))[$],[$]CC(c1cc(Cl)c(Cl)c(Cl)c1)[$],[$]CC(c1c(Cl)cc(Cl)cc1(Cl))[$],[$]CC(c1c(Cl)cc(Cl)cc1(Cl))[$][]}
F2: Original | G2: Inversion | H2: Change in Descriptor ID | I2: Change in descriptor | J2: Duplication | K2: HH PEG | L2: No match since frame shift | M2: Symmetric repeat unit | N2: Duplicated | O2: Matches different polymer since >=1 realization | P2: Bonding descriptors flipped | Q2: Duplicated RU | R2: Frame shift | S2: RU Split | T2: RU Split | U2: Frame shift | V2: Implicit hydrogen | W2: inversion | X2: change to SMARTS | Y2: split | Z2: split + rearrange | AA2: another split | AB2: duplication | AC2: Implicit EG | AD2: flipped EG | AE2: Duplication | AF2: Change in EG SMILES | AG2: RU Split | AH2: EG code | AI2: Duplicated RU | AJ2: RU Split | AK2: Frame shift | AL2: Frame shift | AM2: PS | AN2: Change in SMILES | AO2: Chain growth + inversion | AP2: Inversion | AQ2: Duplication | AR2: Change in SMILES | AS2: Change in Descriptor ID | AT2: HHTT Conjugate | AU2: HHTT Conjugate | AV2: Polyethylene backbone | AW2: Change bonding descriptors | AX2: Polyethylene backbone | AY2: HT but same backbone | AZ2: different SMILES | BA2: HH-TT PVC | BB2: Duplicated | BC2: Adding [$] to symmetric RU | BD2: Adding [$] to symmetric RU | BE2: Copolymer with EG | BF2: Change bonding descriptors | BG2: RU Split | BH2: RU order flipped | BI2: Duplicated RU | BJ2: Flipped EG | BK2: Wrong terminal descriptor, no match | BL2: Copolymer with complex pendant group | BM2: RU Split | BN2: flipped RU | BO2: Implicit-Explicit representation | BP2: Chain-Growth Copolymer | BQ2: Switch RU order | BR2: RU Split | BS2: RU Split | BT2: RU Duplication | BU2: Double bond | BV2: Add bonding descriptors | BW2: Realization in EG, no match | BX2: HT, TH | BY2: Change in SMILES | BZ2: HT PB | CA2: Flip of cis | CB2: HHTT PB | CC2: Duplicated RU | CD2: Ring along the backbone | CE2: Change in bonding descriptors | CF2: Duplicated RU | CG2: AABB copolymer | CH2: Equivalent AB (does not hit), but does hit by substructure search | CI2: Flipped repeat units | CJ2: Equivalent AB (does not hit) | CK2: Duplicated RU | CL2: Ring along the backbone | CM2: Duplicated RU | CN2: Duplicated RU | CO2: Equivalent AB representation | CP2: Change in RU order | CQ2: Ring along the backbone | CR2: Change to SMILES | CS2: Change in ring ID | CT2: Change in descriptor ID | CU2: Duplication | CV2: End group | CW2: RU Split | CX2: RU Split, order change | CY2: Flipped EG | CZ2: Flipped bonding descriptors | DA2: Duplication | DB2: Implicit/Explicit Representation | DC2: Complicated Copolymer | DD2: Duplication
E3: # of Matches | F3: =COUNTIF(F5:F1000, 1) | G3: =COUNTIF(G5:G1000, 1) | H3: =COUNTIF(H5:H1000, 1) | I3: =COUNTIF(I5:I1000, 1) | J3: =COUNTIF(J5:J1000, 1) | K3: =COUNTIF(K5:K1000, 1) | L3: =COUNTIF(L5:L1000, 1) | M3: =COUNTIF(M5:M1000, 1) | ... DD3: =COUNTIF(DD5:DD1000, 1)
E4: Case (Right) Topology (Below) | F4: PEG | K4: Wrong bonding descriptor | L4: Frame Shift | O4: Frame shift with EG | V4: Now add hydrogen end groups, hits different than {[][<]CCO[>][]} | AC4: Implicit EG | AH4: Frame Shift PDMS | AM4: Chain-growth copolymer | AV4: Polyethylene backbone | BA4: HH-TT chemistry | BE4: Copolymer with 1 EG | BL4: Copolymer with complex pendant group | BP4: Chain-Growth Copolymer | BU4: Double Bond | BZ4: Symmetric double bond | CD4: Ring along the backbone | CG4: AA-BB copolymer | CL4: Ring along the backbone | CQ4: Ring along the backbone | CV4: End group | DC4: Complicated
A5: {[][<][Si](CC)(CC)O[>][]} | B5: {[][>][Si](CC)(CC)O[<][]} | C5: Poly[oxy(diethylsilylene)] | D5: Bicerano's Book | E5: Single Object | G5: =F5 | H5: =F5 | I5: =F5 | J5: =F5 | P5: =O5 | Q5: =O5 | R5: =O5 | S5: =O5 | T5: =O5 | U5: =O5 | W5: =V5 | X5: =V5 | Y5: =V5 | Z5: =V5 | AA5: =V5 | AB5: =V5 | AD5: =AC5 | AE5: =AC5 | AF5: =AC5 | AG5: =AC5 | AI5: =AH5 | AJ5: =AI5 | AK5: =AJ5 | AL5: =AK5 | AN5: =AM5 | AO5: =AM5 | AP5: =AO5 | AQ5: =AP5 | AR5: =AQ5 | AS5: =AR5 | AT5: =AS5 | AU5: =AT5 | AW5: =AV5 | AX5: =AW5 | AY5: =AX5 | AZ5: =AY5 | BB5: =BA5 | BC5: =BA5 | BD5: =BA5 | BF5: =BE5 | BG5: =BF5 | BH5: =BG5 | BI5: =BH5 | BJ5: =BI5 | BM5: =BL5 | BN5: =BM5 | BO5: =BN5 | BQ5: =BP5 | BR5: =BQ5 | BS5: =BR5 | BT5: =BS5 | BV5: =BU5 | BX5: =BV5 | BY5: =BX5 | CA5: =BZ5 | CB5: =CA5 | CC5: =CB5 | CE5: =CD5 | CF5: =CE5 | CI5: =CG5 | CJ5: =CH5 | CK5: =CI5 | CM5: =CL5 | CN5: =CM5 | CP5: =CN5 | CR5: =CQ5 | CS5: =CR5 | CT5: =CS5 | CU5: =CT5 | CW5: =CV5 | CX5: =CW5 | CY5: =CX5 | CZ5: =CY5 | DA5: =CZ5 | DB5: =DA5 | DD5: =DC5
A6: {[][<][Si](C)(C)O[>][]} | B6: {[][>][Si](C)(C)O[<][]} | C6: Poly(dimethyl siloxane) | D6: Bicerano's Book | E6: Single Object | G6: =F6 | H6: =F6 | I6: =F6 | J6: =F6 | P6: =O6 | Q6: =O6 | R6: =O6 | S6: =O6 | T6: =O6 | U6: =O6 | W6: =V6 | X6: =V6 | Y6: =V6 | Z6: =V6 | AA6: =V6 | AB6: =V6 | AD6: =AC6 | AE6: =AC6 | AF6: =AC6 | AG6: =AC6 | AI6: =AH6 | AJ6: =AI6 | AK6: =AJ6 | AL6: =AK6 | AN6: =AM6 | AO6: =AM6 | AP6: =AO6 | AQ6: =AP6 | AR6: =AQ6 | AS6: =AR6 | AT6: =AS6 | AU6: =AT6 | AW6: =AV6 | AX6: =AW6 | AY6: =AX6 | AZ6: =AY6 | BB6: =BA6 | BC6: =BA6 | BD6: =BA6 | BF6: =BE6 | BG6: =BF6 | BH6: =BG6 | BI6: =BH6 | BJ6: =BI6 | BM6: =BL6 | BN6: =BM6 | BO6: =BN6 | BQ6: =BP6 | BR6: =BQ6 | BS6: =BR6 | BT6: =BS6 | BV6: =BU6 | BX6: =BV6 | BY6: =BV6 | CA6: =BZ6 | CB6: =CA6 | CC6: =CB6 | CE6: =CD6 | CF6: =CE6 | CI6: =CG6 | CJ6: =CH6 | CK6: =CI6 | CM6: =CL6 | CN6: =CM6 | CP6: =CN6 | CR6: =CQ6 | CS6: =CR6 | CT6: =CS6 | CU6: =CT6 | CW6: =CV6 | CX6: =CW6 | CY6: =CX6 | CZ6: =CY6 | DA6: =CZ6 | DB6: =DA6 | DD6: =DC6
A7: {[][$]C\C=C/C[$][]} | B7: {[][>]C/C=C\C[<][]} | C7: Poly(cis-1,4-butadiene) | D7: Bicerano's Book | E7: Single Object | G7: =F7 | H7: =F7 | I7: =F7 | J7: =F7 | P7: =O7 | Q7: =O7 | R7: =O7 | S7: =O7 | T7: =O7 | U7: =O7 | W7: =V7 | X7: =V7 | Y7: =V7 | Z7: =V7 | AA7: =V7 | AB7: =V7 | AD7: =AC7 | AE7: =AC7 | AF7: =AC7 | AG7: =AC7 | AI7: =AH7 | AJ7: =AI7 | AK7: =AJ7 | AL7: =AK7 | AN7: =AM7 | AO7: =AM7 | AP7: =AO7 | AQ7: =AP7 | AR7: =AQ7 | AS7: =AR7 | AT7: =AS7 | AU7: =AT7 | AW7: =AV7 | AX7: =AW7 | AY7: =AX7 | AZ7: =AY7 | BB7: =BA7 | BC7: =BA7 | BD7: =BA7 | BF7: =BE7 | BG7: =BF7 | BH7: =BG7 | BI7: =BH7 | BJ7: =BI7 | BM7: =BL7 | BN7: =BM7 | BO7: =BN7 | BQ7: =BP7 | BR7: =BQ7 | BS7: =BR7 | BT7: =BS7 | BV7: =BU7 | BX7: =BV7 | BY7: =BV7 | BZ7: 1 | CA7: =BZ7 | CB7: =CA7 | CC7: =CB7 | CE7: =CD7 | CF7: =CE7 | CI7: =CG7 | CJ7: =CH7 | CK7: =CI7 | CM7: =CL7 | CN7: =CM7 | CP7: =CN7 | CR7: =CQ7 | CS7: =CR7 | CT7: =CS7 | CU7: =CT7 | CW7: =CV7 | CX7: =CW7 | CY7: =CX7 | CZ7: =CY7 | DA7: =CZ7 | DB7: =DA7 | DD7: =DC7
A8: {[][<]C[Si](C)(C)[>][]} | B8: {[][>][Si](C)(C)C[<][]} | C8: Poly(dimethylsilylenemethylene) | D8: Bicerano's Book | E8: Single Object | G8: =F8 | H8: =F8 | I8: =F8 | J8: =F8 | P8: =O8 | Q8: =O8 | R8: =O8 | S8: =O8 | T8: =O8 | U8: =O8 | W8: =V8 | X8: =V8 | Y8: =V8 | Z8: =V8 | AA8: =V8 | AB8: =V8 | AD8: =AC8 | AE8: =AC8 | AF8: =AC8 | AG8: =AC8 | AI8: =AH8 | AJ8: =AI8 | AK8: =AJ8 | AL8: =AK8 | AN8: =AM8 | AO8: =AM8 | AP8: =AO8 | AQ8: =AP8 | AR8: =AQ8 | AS8: =AR8 | AT8: =AS8 | AU8: =AT8 | AW8: =AV8 | AX8: =AW8 | AY8: =AX8 | AZ8: =AY8 | BB8: =BA8 | BC8: =BA8 | BD8: =BA8 | BF8: =BE8 | BG8: =BF8 | BH8: =BG8 | BI8: =BH8 | BJ8: =BI8 | BM8: =BL8 | BN8: =BM8 | BO8: =BN8 | BQ8: =BP8 | BR8: =BQ8 | BS8: =BR8 | BT8: =BS8 | BV8: =BU8 | BX8: =BV8 | BY8: =BV8 | CA8: =BZ8 | CB8: =CA8 | CC8: =CB8 | CE8: =CD8 | CF8: =CE8 | CI8: =CG8 | CJ8: =CH8 | CK8: =CI8 | CM8: =CL8 | CN8: =CM8 | CP8: =CN8 | CR8: =CQ8 | CS8: =CR8 | CT8: =CS8 | CU8: =CT8 | CW8: =CV8 | CX8: =CW8 | CY8: =CX8 | CZ8: =CY8 | DA8: =CZ8 | DB8: =DA8 | DD8: =DC8
A9: {[][<][Si](c1ccccc1)(C)O[>][]} | B9: {[][>][Si](c(cc1)ccc1)(C)O[<][]} | C9: Poly[oxy(methylphenylsilylene)] | D9: Bicerano's Book | E9: Single Object | G9: =F9 | H9: =F9 | I9: =F9 | J9: =F9 | P9: =O9 | Q9: =O9 | R9: =O9 | S9: =O9 | T9: =O9 | U9: =O9 | W9: =V9 | X9: =V9 | Y9: =V9 | Z9: =V9 | AA9: =V9 | AB9: =V9 | AD9: =AC9 | AE9: =AC9 | AF9: =AC9 | AG9: =AC9 | AI9: =AH9 | AJ9: =AI9 | AK9: =AJ9 | AL9: =AK9 | AN9: =AM9 | AO9: =AM9 | AP9: =AO9 | AQ9: =AP9 | AR9: =AQ9 | AS9: =AR9 | AT9: =AS9 | AU9: =AT9 | AW9: =AV9 | AX9: =AW9 | AY9: =AX9 | AZ9: =AY9 | BB9: =BA9 | BC9: =BA9 | BD9: =BA9 | BF9: =BE9 | BG9: =BF9 | BH9: =BG9 | BI9: =BH9 | BJ9: =BI9 | BM9: =BL9 | BN9: =BM9 | BO9: =BN9 | BQ9: =BP9 | BR9: =BQ9 | BS9: =BR9 | BT9: =BS9 | BV9: =BU9 | BX9: =BV9 | BY9: =BV9 | CA9: =BZ9 | CB9: =CA9 | CC9: =CB9 | CE9: =CD9 | CF9: =CE9 | CI9: =CG9 | CJ9: =CH9 | CK9: =CI9 | CM9: =CL9 | CN9: =CM9 | CP9: =CN9 | CR9: =CQ9 | CS9: =CR9 | CT9: =CS9 | CU9: =CT9 | CW9: =CV9 | CX9: =CW9 | CY9: =CX9 | CZ9: =CY9 | DA9: =CZ9 | DB9: =DA9 | DD9: =DC9
A10: {[][<]CC(COCCCCCC)O[>],[<]C(COCCCCCC)CO[>][]} | B10: {[][>]OCC(COCCCCCC)[<],[>]OC(COCCCCCC)C[<][]} | C10: Poly(3-hexoxypropylene oxide) | D10: Bicerano's Book | E10: Single Object | G10: =F10 | H10: =F10 | I10: =F10 | J10: =F10 | P10: =O10 | Q10: =O10 | R10: =O10 | S10: =O10 | T10: =O10 | U10: =O10 | W10: =V10 | X10: =V10 | Y10: =V10 | Z10: =V10 | AA10: =V10 | AB10: =V10 | AD10: =AC10 | AE10: =AC10 | AF10: =AC10 | AG10: =AC10 | AI10: =AH10 | AJ10: =AI10 | AK10: =AJ10 | AL10: =AK10 | AN10: =AM10 | AO10: =AM10 | AP10: =AO10 | AQ10: =AP10 | AR10: =AQ10 | AS10: =AR10 | AT10: =AS10 | AU10: =AT10 | AW10: =AV10 | AX10: =AW10 | AY10: =AX10 | AZ10: =AY10 | BB10: =BA10 | BC10: =BA10 | BD10: =BA10 | BF10: =BE10 | BG10: =BF10 | BH10: =BG10 | BI10: =BH10 | BJ10: =BI10 | BM10: =BL10 | BN10: =BM10 | BO10: =BN10 | BQ10: =BP10 | BR10: =BQ10 | BS10: =BR10 | BT10: =BS10 | BV10: =BU10 | BX10: =BV10 | BY10: =BV10 | CA10: =BZ10 | CB10: =CA10 | CC10: =CB10 | CE10: =CD10 | CF10: =CE10 | CI10: =CG10 | CJ10: =CH10 | CK10: =CI10 | CM10: =CL10 | CN10: =CM10 | CP10: =CN10 | CR10: =CQ10 | CS10: =CR10 | CT10: =CS10 | CU10: =CT10 | CW10: =CV10 | CX10: =CW10 | CY10: =CX10 | CZ10: =CY10 | DA10: =CZ10 | DB10: =DA10 | DD10: =DC10
A11: {[][<]CCCCO[>][]} | B11: {[][>]OCCCC[<][]} | C11: Polyoxytetramethylene | D11: Bicerano's Book | E11: Single Object | G11: =F11 | H11: =F11 | I11: =F11 | J11: =F11 | P11: =O11 | Q11: =O11 | R11: =O11 | S11: =O11 | T11: =O11 | U11: =O11 | W11: =V11 | X11: =V11 | Y11: =V11 | Z11: =V11 | AA11: =V11 | AB11: =V11 | AD11: =AC11 | AE11: =AC11 | AF11: =AC11 | AG11: =AC11 | AI11: =AH11 | AJ11: =AI11 | AK11: =AJ11 | AL11: =AK11 | AN11: =AM11 | AO11: =AM11 | AP11: =AO11 | AQ11: =AP11 | AR11: =AQ11 | AS11: =AR11 | AT11: =AS11 | AU11: =AT11 | AW11: =AV11 | AX11: =AW11 | AY11: =AX11 | AZ11: =AY11 | BB11: =BA11 | BC11: =BA11 | BD11: =BA11 | BF11: =BE11 | BG11: =BF11 | BH11: =BG11 | BI11: =BH11 | BJ11: =BI11 | BM11: =BL11 | BN11: =BM11 | BO11: =BN11 | BQ11: =BP11 | BR11: =BQ11 | BS11: =BR11 | BT11: =BS11 | BV11: =BU11 | BX11: =BV11 | BY11: =BV11 | CA11: =BZ11 | CB11: =CA11 | CC11: =CB11 | CE11: =CD11 | CF11: =CE11 | CI11: =CG11 | CJ11: =CH11 | CK11: =CI11 | CM11: =CL11 | CN11: =CM11 | CP11: =CN11 | CR11: =CQ11 | CS11: =CR11 | CT11: =CS11 | CU11: =CT11 | CW11: =CV11 | CX11: =CW11 | CY11: =CX11 | CZ11: =CY11 | DA11: =CZ11 | DB11: =DA11 | DD11: =DC11
A12: {[][<][Si](C)(C)N[>][]} | B12: {[][>][Si](C)(C)N[<][]} | C12: Poly(1,1-dimethylsilazane) | D12: Bicerano's Book | E12: Single Object | G12: =F12 | H12: =F12 | I12: =F12 | J12: =F12 | P12: =O12 | Q12: =O12 | R12: =O12 | S12: =O12 | T12: =O12 | U12: =O12 | W12: =V12 | X12: =V12 | Y12: =V12 | Z12: =V12 | AA12: =V12 | AB12: =V12 | AD12: =AC12 | AE12: =AC12 | AF12: =AC12 | AG12: =AC12 | AI12: =AH12 | AJ12: =AI12 | AK12: =AJ12 | AL12: =AK12 | AN12: =AM12 | AO12: =AM12 | AP12: =AO12 | AQ12: =AP12 | AR12: =AQ12 | AS12: =AR12 | AT12: =AS12 | AU12: =AT12 | AW12: =AV12 | AX12: =AW12 | AY12: =AX12 | AZ12: =AY12 | BB12: =BA12 | BC12: =BA12 | BD12: =BA12 | BF12: =BE12 | BG12: =BF12 | BH12: =BG12 | BI12: =BH12 | BJ12: =BI12 | BM12: =BL12 | BN12: =BM12 | BO12: =BN12 | BQ12: =BP12 | BR12: =BQ12 | BS12: =BR12 | BT12: =BS12 | BV12: =BU12 | BX12: =BV12 | BY12: =BV12 | CA12: =BZ12 | CB12: =CA12 | CC12: =CB12 | CE12: =CD12 | CF12: =CE12 | CI12: =CG12 | CJ12: =CH12 | CK12: =CI12 | CM12: =CL12 | CN12: =CM12 | CP12: =CN12 | CR12: =CQ12 | CS12: =CR12 | CT12: =CS12 | CU12: =CT12 | CW12: =CV12 | CX12: =CW12 | CY12: =CX12 | CZ12: =CY12 | DA12: =CZ12 | DB12: =DA12 | DD12: =DC12
A13: {[][$]CC=C(CCCC)C[$][]} | B13: {[][>]CC=C(CCCC)C[<],[>]CC(CCCC)=CC[<][]} | C13: Poly(2-n-butyl-1,4-butadiene) | D13: Bicerano's Book | E13: Single Object | G13: =F13 | H13: =F13 | I13: =F13 | J13: =F13 | P13: =O13 | Q13: =O13 | R13: =O13 | S13: =O13 | T13: =O13 | U13: =O13 | W13: =V13 | X13: =V13 | Y13: =V13 | Z13: =V13 | AA13: =V13 | AB13: =V13 | AD13: =AC13 | AE13: =AC13 | AF13: =AC13 | AG13: =AC13 | AI13: =AH13 | AJ13: =AI13 | AK13: =AJ13 | AL13: =AK13 | AN13: =AM13 | AO13: =AM13 | AP13: =AO13 | AQ13: =AP13 | AR13: =AQ13 | AS13: =AR13 | AT13: =AS13 | AU13: =AT13 | AW13: =AV13 | AX13: =AW13 | AY13: =AX13 | AZ13: =AY13 | BB13: =BA13 | BC13: =BA13 | BD13: =BA13 | BF13: =BE13 | BG13: =BF13 | BH13: =BG13 | BI13: =BH13 | BJ13: =BI13 | BM13: =BL13 | BN13: =BM13 | BO13: =BN13 | BQ13: =BP13 | BR13: =BQ13 | BS13: =BR13 | BT13: =BS13 | BV13: =BU13 | BX13: =BV13 | BY13: =BV13 | CA13: =BZ13 | CB13: =CA13 | CC13: =CB13 | CE13: =CD13 | CF13: =CE13 | CI13: =CG13 | CJ13: =CH13 | CK13: =CI13 | CM13: =CL13 | CN13: =CM13 | CP13: =CN13 | CR13: =CQ13 | CS13: =CR13 | CT13: =CS13 | CU13: =CT13 | CW13: =CV13 | CX13: =CW13 | CY13: =CX13 | CZ13: =CY13 | DA13: =CZ13 | DB13: =DA13 | DD13: =DC13
A14: {[][$]CC(OCCCCCCCC)[$][]} | B14: {[][>]CC(OCCCCCCCC)[<],[>]C(OCCCCCCCC)C[<][]} | C14: Poly(vinyl n-octyl ether) | D14: Bicerano's Book | E14: Single Object | G14: =F14 | H14: =F14 | I14: =F14 | J14: =F14 | P14: =O14 | Q14: =O14 | R14: =O14 | S14: =O14 | T14: =O14 | U14: =O14 | W14: =V14 | X14: =V14 | Y14: =V14 | Z14: =V14 | AA14: =V14 | AB14: =V14 | AD14: =AC14 | AE14: =AC14 | AF14: =AC14 | AG14: =AC14 | AI14: =AH14 | AJ14: =AI14 | AK14: =AJ14 | AL14: =AK14 | AN14: =AM14 | AO14: =AM14 | AP14: =AO14 | AQ14: =AP14 | AR14: =AQ14 | AS14: =AR14 | AT14: =AS14 | AU14: =AT14 | AW14: =AV14 | AX14: =AW14 | AY14: =AX14 | AZ14: =AY14 | BB14: =BA14 | BC14: =BA14 | BD14: =BA14 | BF14: =BE14 | BG14: =BF14 | BH14: =BG14 | BI14: =BH14 | BJ14: =BI14 | BM14: =BL14 | BN14: =BM14 | BO14: =BN14 | BQ14: =BP14 | BR14: =BQ14 | BS14: =BR14 | BT14: =BS14 | BV14: =BU14 | BX14: =BV14 | BY14: =BV14 | CA14: =BZ14 | CB14: =CA14 | CC14: =CB14 | CE14: =CD14 | CF14: =CE14 | CI14: =CG14 | CJ14: =CH14 | CK14: =CI14 | CM14: =CL14 | CN14: =CM14 | CP14: =CN14 | CR14: =CQ14 | CS14: =CR14 | CT14: =CS14 | CU14: =CT14 | CW14: =CV14 | CX14: =CW14 | CY14: =CX14 | CZ14: =CY14 | DA14: =CZ14 | DB14: =DA14 | DD14: =DC14
A15: {[][<]CC(COCCCC)O[>],[<]C(COCCCC)CO[>][]} | B15: {[][>]OCC(COCCCC)[<],[>]OC(COCCCC)C[<][]} | C15: Poly(3-butoxypropylene oxide) | D15: Bicerano's Book | E15: Single Object | G15: =F15 | H15: =F15 | I15: =F15 | J15: =F15 | P15: =O15 | Q15: =O15 | R15: =O15 | S15: =O15 | T15: =O15 | U15: =O15 | W15: =V15 | X15: =V15 | Y15: =V15 | Z15: =V15 | AA15: =V15 | AB15: =V15 | AD15: =AC15 | AE15: =AC15 | AF15: =AC15 | AG15: =AC15 | AI15: =AH15 | AJ15: =AI15 | AK15: =AJ15 | AL15: =AK15 | AN15: =AM15 | AO15: =AM15 | AP15: =AO15 | AQ15: =AP15 | AR15: =AQ15 | AS15: =AR15 | AT15: =AS15 | AU15: =AT15 | AW15: =AV15 | AX15: =AW15 | AY15: =AX15 | AZ15: =AY15 | BB15: =BA15 | BC15: =BA15 | BD15: =BA15 | BF15: =BE15 | BG15: =BF15 | BH15: =BG15 | BI15: =BH15 | BJ15: =BI15 | BM15: =BL15 | BN15: =BM15 | BO15: =BN15 | BQ15: =BP15 | BR15: =BQ15 | BS15: =BR15 | BT15: =BS15 | BV15: =BU15 | BX15: =BV15 | BY15: =BV15 | CA15: =BZ15 | CB15: =CA15 | CC15: =CB15 | CE15: =CD15 | CF15: =CE15 | CI15: =CG15 | CJ15: =CH15 | CK15: =CI15 | CM15: =CL15 | CN15: =CM15 | CP15: =CN15 | CR15: =CQ15 | CS15: =CR15 | CT15: =CS15 | CU15: =CT15 | CW15: =CV15 | CX15: =CW15 | CY15: =CX15 | CZ15: =CY15 | DA15: =CZ15 | DB15: =DA15 | DD15: =DC15
A16: {[][$]CC[$][]} | B16: {[][>]CC[<][]} | C16: Polyethylene | D16: Bicerano's Book | E16: Single Object | G16: =F16 | H16: =F16 | I16: =F16 | J16: =F16 | P16: =O16 | Q16: =O16 | R16: =O16 | S16: =O16 | T16: =O16 | U16: =O16 | W16: =V16 | X16: =V16 | Y16: =V16 | Z16: =V16 | AA16: =V16 | AB16: =V16 | AD16: =AC16 | AE16: =AC16 | AF16: =AC16 | AG16: =AC16 | AI16: =AH16 | AJ16: =AI16 | AK16: =AJ16 | AL16: =AK16 | AN16: =AM16 | AO16: =AM16 | AP16: =AO16 | AQ16: =AP16 | AR16: =AQ16 | AS16: =AR16 | AT16: =AS16 | AU16: =AT16 | AV16: 1 | AW16: =AV16 | AX16: =AW16 | AY16: =AX16 | AZ16: =AY16 | BB16: =BA16 | BC16: =BA16 | BD16: =BA16 | BF16: =BE16 | BG16: =BF16 | BH16: =BG16 | BI16: =BH16 | BJ16: =BI16 | BM16: =BL16 | BN16: =BM16 | BO16: =BN16 | BQ16: =BP16 | BR16: =BQ16 | BS16: =BR16 | BT16: =BS16 | BV16: =BU16 | BX16: =BV16 | BY16: =BV16 | CA16: =BZ16 | CB16: =CA16 | CC16: =CB16 | CE16: =CD16 | CF16: =CE16 | CI16: =CG16 | CJ16: =CH16 | CK16: =CI16 | CM16: =CL16 | CN16: =CM16 | CP16: =CN16 | CR16: =CQ16 | CS16: =CR16 | CT16: =CS16 | CU16: =CT16 | CW16: =CV16 | CX16: =CW16 | CY16: =CX16 | CZ16: =CY16 | DA16: =CZ16 | DB16: =DA16 | DD16: =DC16
A17: {[][<]CCCO[>][]} | B17: {[][>]OCCC[<][]} | C17: Polyoxytrimethylene | D17: Bicerano's Book | E17: Single Object | G17: =F17 | H17: =F17 | I17: =F17 | J17: =F17 | P17: =O17 | Q17: =O17 | R17: =O17 | S17: =O17 | T17: =O17 | U17: =O17 | W17: =V17 | X17: =V17 | Y17: =V17 | Z17: =V17 | AA17: =V17 | AB17: =V17 | AD17: =AC17 | AE17: =AC17 | AF17: =AC17 | AG17: =AC17 | AI17: =AH17 | AJ17: =AI17 | AK17: =AJ17 | AL17: =AK17 | AN17: =AM17 | AO17: =AM17 | AP17: =AO17 | AQ17: =AP17 | AR17: =AQ17 | AS17: =AR17 | AT17: =AS17 | AU17: =AT17 | AW17: =AV17 | AX17: =AW17 | AY17: =AX17 | AZ17: =AY17 | BB17: =BA17 | BC17: =BA17 | BD17: =BA17 | BF17: =BE17 | BG17: =BF17 | BH17: =BG17 | BI17: =BH17 | BJ17: =BI17 | BM17: =BL17 | BN17: =BM17 | BO17: =BN17 | BQ17: =BP17 | BR17: =BQ17 | BS17: =BR17 | BT17: =BS17 | BV17: =BU17 | BX17: =BV17 | BY17: =BV17 | CA17: =BZ17 | CB17: =CA17 | CC17: =CB17 | CE17: =CD17 | CF17: =CE17 | CI17: =CG17 | CJ17: =CH17 | CK17: =CI17 | CM17: =CL17 | CN17: =CM17 | CP17: =CN17 | CR17: =CQ17 | CS17: =CR17 | CT17: =CS17 | CU17: =CT17 | CW17: =CV17 | CX17: =CW17 | CY17: =CX17 | CZ17: =CY17 | DA17: =CZ17 | DB17: =DA17 | DD17: =DC17
A18: {[][$]CC=C(CCC)C[$][]} | B18: {[][>]CC=C(CCC)C[<],[>]CC(CCC)=CC[<][]} | C18: Poly(2-n-propyl-1,4-butadiene) | D18: Bicerano's Book | E18: Single Object | G18: =F18 | H18: =F18 | I18: =F18 | J18: =F18 | P18: =O18 | Q18: =O18 | R18: =O18 | S18: =O18 | T18: =O18 | U18: =O18 | W18: =V18 | X18: =V18 | Y18: =V18 | Z18: =V18 | AA18: =V18 | AB18: =V18 | AD18: =AC18 | AE18: =AC18 | AF18: =AC18 | AG18: =AC18 | AI18: =AH18 | AJ18: =AI18 | AK18: =AJ18 | AL18: =AK18 | AN18: =AM18 | AO18: =AM18 | AP18: =AO18 | AQ18: =AP18 | AR18: =AQ18 | AS18: =AR18 | AT18: =AS18 | AU18: =AT18 | AW18: =AV18 | AX18: =AW18 | AY18: =AX18 | AZ18: =AY18 | BB18: =BA18 | BC18: =BA18 | BD18: =BA18 | BF18: =BE18 | BG18: =BF18 | BH18: =BG18 | BI18: =BH18 | BJ18: =BI18 | BM18: =BL18 | BN18: =BM18 | BO18: =BN18 | BQ18: =BP18 | BR18: =BQ18 | BS18: =BR18 | BT18: =BS18 | BU18: 1 | BV18: =BU18 | BX18: =BV18 | BY18: =BV18 | CA18: =BZ18 | CB18: =CA18 | CC18: =CB18 | CE18: =CD18 | CF18: =CE18 | CI18: =CG18 | CJ18: =CH18 | CK18: =CI18 | CM18: =CL18 | CN18: =CM18 | CP18: =CN18 | CR18: =CQ18 | CS18: =CR18 | CT18: =CS18 | CU18: =CT18 | CW18: =CV18 | CX18: =CW18 | CY18: =CX18 | CZ18: =CY18 | DA18: =CZ18 | DB18: =DA18 | DD18: =DC18
A19: {[][$]CC(OCCCCCCCCCC)[$][]} | B19: {[][>]CC(OCCCCCCCCCC)[<],[>]C(OCCCCCCCCCC)C[<][]} | C19: Poly(vinyl n-decyl ether) | D19: Bicerano's Book | E19: Single Object | G19: =F19 | H19: =F19 | I19: =F19 | J19: =F19 | P19: =O19 | Q19: =O19 | R19: =O19 | S19: =O19 | T19: =O19 | U19: =O19 | W19: =V19 | X19: =V19 | Y19: =V19 | Z19: =V19 | AA19: =V19 | AB19: =V19 | AD19: =AC19 | AE19: =AC19 | AF19: =AC19 | AG19: =AC19 | AI19: =AH19 | AJ19: =AI19 | AK19: =AJ19 | AL19: =AK19 | AN19: =AM19 | AO19: =AM19 | AP19: =AO19 | AQ19: =AP19 | AR19: =AQ19 | AS19: =AR19 | AT19: =AS19 | AU19: =AT19 | AW19: =AV19 | AX19: =AW19 | AY19: =AX19 | AZ19: =AY19 | BB19: =BA19 | BC19: =BA19 | BD19: =BA19 | BF19: =BE19 | BG19: =BF19 | BH19: =BG19 | BI19: =BH19 | BJ19: =BI19 | BM19: =BL19 | BN19: =BM19 | BO19: =BN19 | BQ19: =BP19 | BR19: =BQ19 | BS19: =BR19 | BT19: =BS19 | BV19: =BU19 | BX19: =BV19 | BY19: =BV19 | CA19: =BZ19 | CB19: =CA19 | CC19: =CB19 | CE19: =CD19 | CF19: =CE19 | CI19: =CG19 | CJ19: =CH19 | CK19: =CI19 | CM19: =CL19 | CN19: =CM19 | CP19: =CN19 | CR19: =CQ19 | CS19: =CR19 | CT19: =CS19 | CU19: =CT19 | CW19: =CV19 | CX19: =CW19 | CY19: =CX19 | CZ19: =CY19 | DA19: =CZ19 | DB19: =DA19 | DD19: =DC19
A20: {[][$]CC=C(CC)C[$][]} | B20: {[][>]CC=C(CC)C[<],[>]CC(CC)=CC[<][]} | C20: Poly(2-ethyl-1,4-butadiene) | D20: Bicerano's Book | E20: Single Object | G20: =F20 | H20: =F20 | I20: =F20 | J20: =F20 | P20: =O20 | Q20: =O20 | R20: =O20 | S20: =O20 | T20: =O20 | U20: =O20 | W20: =V20 | X20: =V20 | Y20: =V20 | Z20: =V20 | AA20: =V20 | AB20: =V20 | AD20: =AC20 | AE20: =AC20 | AF20: =AC20 | AG20: =AC20 | AI20: =AH20 | AJ20: =AI20 | AK20: =AJ20 | AL20: =AK20 | AN20: =AM20 | AO20: =AM20 | AP20: =AO20 | AQ20: =AP20 | AR20: =AQ20 | AS20: =AR20 | AT20: =AS20 | AU20: =AT20 | AW20: =AV20 | AX20: =AW20 | AY20: =AX20 | AZ20: =AY20 | BB20: =BA20 | BC20: =BA20 | BD20: =BA20 | BF20: =BE20 | BG20: =BF20 | BH20: =BG20 | BI20: =BH20 | BJ20: =BI20 | BM20: =BL20 | BN20: =BM20 | BO20: =BN20 | BQ20: =BP20 | BR20: =BQ20 | BS20: =BR20 | BT20: =BS20 | BV20: =BU20 | BX20: =BV20 | BY20: =BV20 | CA20: =BZ20 | CB20: =CA20 | CC20: =CB20 | CE20: =CD20 | CF20: =CE20 | CI20: =CG20 | CJ20: =CH20 | CK20: =CI20 | CM20: =CL20 | CN20: =CM20 | CP20: =CN20 | CR20: =CQ20 | CS20: =CR20 | CT20: =CS20 | CU20: =CT20 | CW20: =CV20 | CX20: =CW20 | CY20: =CX20 | CZ20: =CY20 | DA20: =CZ20 | DB20: =DA20 | DD20: =DC20
A21: {[][<][Si](C)(CCC(F)(F)F)O[>][]} | B21: {[][>][Si](CCC(F)(F)F)(C)O[<][]} | C21: Poly[oxy(methyl γ-trifluoropropylsilylene)] | D21: Bicerano's Book | E21: Single Object | G21: =F21 | H21: =F21 | I21: =F21 | J21: =F21 | P21: =O21 | Q21: =O21 | R21: =O21 | S21: =O21 | T21: =O21 | U21: =O21 | W21: =V21 | X21: =V21 | Y21: =V21 | Z21: =V21 | AA21: =V21 | AB21: =V21 | AD21: =AC21 | AE21: =AC21 | AF21: =AC21 | AG21: =AC21 | AI21: =AH21 | AJ21: =AI21 | AK21: =AJ21 | AL21: =AK21 | AN21: =AM21 | AO21: =AM21 | AP21: =AO21 | AQ21: =AP21 | AR21: =AQ21 | AS21: =AR21 | AT21: =AS21 | AU21: =AT21 | AW21: =AV21 | AX21: =AW21 | AY21: =AX21 | AZ21: =AY21 | BB21: =BA21 | BC21: =BA21 | BD21: =BA21 | BF21: =BE21 | BG21: =BF21 | BH21: =BG21 | BI21: =BH21 | BJ21: =BI21 | BM21: =BL21 | BN21: =BM21 | BO21: =BN21 | BQ21: =BP21 | BR21: =BQ21 | BS21: =BR21 | BT21: =BS21 | BV21: =BU21 | BX21: =BV21 | BY21: =BV21 | CA21: =BZ21 | CB21: =CA21 | CC21: =CB21 | CE21: =CD21 | CF21: =CE21 | CI21: =CG21 | CJ21: =CH21 | CK21: =CI21 | CM21: =CL21 | CN21: =CM21 | CP21: =CN21 | CR21: =CQ21 | CS21: =CR21 | CT21: =CS21 | CU21: =CT21 | CW21: =CV21 | CX21: =CW21 | CY21: =CX21 | CZ21: =CY21 | DA21: =CZ21 | DB21: =DA21 | DD21: =DC21
A22: {[][$]CC(C)(C)[$][]} | B22: {[][>]CC(C)(C)[<],[>]C(C)(C)C[<][]} | C22: Polyisobutylene | D22: Bicerano's Book | E22: Single Object | G22: =F22 | H22: =F22 | I22: =F22 | J22: =F22 | P22: =O22 | Q22: =O22 | R22: =O22 | S22: =O22 | T22: =O22 | U22: =O22 | W22: =V22 | X22: =V22 | Y22: =V22 | Z22: =V22 | AA22: =V22 | AB22: =V22 | AD22: =AC22 | AE22: =AC22 | AF22: =AC22 | AG22: =AC22 | AI22: =AH22 | AJ22: =AI22 | AK22: =AJ22 | AL22: =AK22 | AN22: =AM22 | AO22: =AM22 | AP22: =AO22 | AQ22: =AP22 | AR22: =AQ22 | AS22: =AR22 | AT22: =AS22 | AU22: =AT22 | AW22: =AV22 | AX22: =AW22 | AY22: =AX22 | AZ22: =AY22 | BB22: =BA22 | BC22: =BA22 | BD22: =BA22 | BF22: =BE22 | BG22: =BF22 | BH22: =BG22 | BI22: =BH22 | BJ22: =BI22 | BM22: =BL22 | BN22: =BM22 | BO22: =BN22 | BQ22: =BP22 | BR22: =BQ22 | BS22: =BR22 | BT22: =BS22 | BV22: =BU22 | BX22: =BV22 | BY22: =BV22 | CA22: =BZ22 | CB22: =CA22 | CC22: =CB22 | CE22: =CD22 | CF22: =CE22 | CI22: =CG22 | CJ22: =CH22 | CK22: =CI22 | CM22: =CL22 | CN22: =CM22 | CP22: =CN22 | CR22: =CQ22 | CS22: =CR22 | CT22: =CS22 | CU22: =CT22 | CW22: =CV22 | CX22: =CW22 | CY22: =CX22 | CZ22: =CY22 | DA22: =CZ22 | DB22: =DA22 | DD22: =DC22
A23: {[][<]CCC[Si](C)(C)[>][]} | B23: {[][>][Si](C)(C)CCC[<][]} | C23: Poly(dimethylsilylenetrimethylene) | D23: Bicerano's Book | E23: Single Object | G23: =F23 | H23: =F23 | I23: =F23 | J23: =F23 | P23: =O23 | Q23: =O23 | R23: =O23 | S23: =O23 | T23: =O23 | U23: =O23 | W23: =V23 | X23: =V23 | Y23: =V23 | Z23: =V23 | AA23: =V23 | AB23: =V23 | AD23: =AC23 | AE23: =AC23 | AF23: =AC23 | AG23: =AC23 | AI23: =AH23 | AJ23: =AI23 | AK23: =AJ23 | AL23: =AK23 | AN23: =AM23 | AO23: =AM23 | AP23: =AO23 | AQ23: =AP23 | AR23: =AQ23 | AS23: =AR23 | AT23: =AS23 | AU23: =AT23 | AW23: =AV23 | AX23: =AW23 | AY23: =AX23 | AZ23: =AY23 | BB23: =BA23 | BC23: =BA23 | BD23: =BA23 | BF23: =BE23 | BG23: =BF23 | BH23: =BG23 | BI23: =BH23 | BJ23: =BI23 | BM23: =BL23 | BN23: =BM23 | BO23: =BN23 | BQ23: =BP23 | BR23: =BQ23 | BS23: =BR23 | BT23: =BS23 | BV23: =BU23 | BX23: =BV23 | BY23: =BV23 | CA23: =BZ23 | CB23: =CA23 | CC23: =CB23 | CE23: =CD23 | CF23: =CE23 | CI23: =CG23 | CJ23: =CH23 | CK23: =CI23 | CM23: =CL23 | CN23: =CM23 | CP23: =CN23 | CR23: =CQ23 | CS23: =CR23 | CT23: =CS23 | CU23: =CT23 | CW23: =CV23 | CX23: =CW23 | CY23: =CX23 | CZ23: =CY23 | DA23: =CZ23 | DB23: =DA23 | DD23: =DC23
A24: {[][<]CCCCCCCCO[>][]} | B24: {[][>]OCCCCCCCC[<][]} | C24: Polyoxyoctamethylene | D24: Bicerano's Book | E24: Single Object | G24: =F24 | H24: =F24 | I24: =F24 | J24: =F24 | P24: =O24 | Q24: =O24 | R24: =O24 | S24: =O24 | T24: =O24 | U24: =O24 | W24: =V24 | X24: =V24 | Y24: =V24 | Z24: =V24 | AA24: =V24 | AB24: =V24 | AD24: =AC24 | AE24: =AC24 | AF24: =AC24 | AG24: =AC24 | AI24: =AH24 | AJ24: =AI24 | AK24: =AJ24 | AL24: =AK24 | AN24: =AM24 | AO24: =AM24 | AP24: =AO24 | AQ24: =AP24 | AR24: =AQ24 | AS24: =AR24 | AT24: =AS24 | AU24: =AT24 | AW24: =AV24 | AX24: =AW24 | AY24: =AX24 | AZ24: =AY24 | BB24: =BA24 | BC24: =BA24 | BD24: =BA24 | BF24: =BE24 | BG24: =BF24 | BH24: =BG24 | BI24: =BH24 | BJ24: =BI24 | BM24: =BL24 | BN24: =BM24 | BO24: =BN24 | BQ24: =BP24 | BR24: =BQ24 | BS24: =BR24 | BT24: =BS24 | BV24: =BU24 | BX24: =BV24 | BY24: =BV24 | CA24: =BZ24 | CB24: =CA24 | CC24: =CB24 | CE24: =CD24 | CF24: =CE24 | CI24: =CG24 | CJ24: =CH24 | CK24: =CI24 | CM24: =CL24 | CN24: =CM24 | CP24: =CN24 | CR24: =CQ24 | CS24: =CR24 | CT24: =CS24 | CU24: =CT24 | CW24: =CV24 | CX24: =CW24 | CY24: =CX24 | CZ24: =CY24 | DA24: =CZ24 | DB24: =DA24 | DD24: =DC24
A25: {[][$]CC=C(C)C[$],[$]CC(C(C)=C)[$],[$]CC(C)(C=C)[$][]} | B25: {[][>]CC(C(=C)C)[<],[>]C(C(=C)C)C[<],[>]CC(C)(C=C)[<],[>]C(C)(C=C)C[<],[>]CC=C(C)C[<],[>]CC(C)=CC[<][]} | C25: Polyisoprene | D25: Bicerano's Book | E25: Single Object | G25: =F25 | H25: =F25 | I25: =F25 | J25: =F25 | P25: =O25 | Q25: =O25 | R25: =O25 | S25: =O25 | T25: =O25 | U25: =O25 | W25: =V25 | X25: =V25 | Y25: =V25 | Z25: =V25 | AA25: =V25 | AB25: =V25 | AD25: =AC25 | AE25: =AC25 | AF25: =AC25 | AG25: =AC25 | AI25: =AH25 | AJ25: =AI25 | AK25: =AJ25 | AL25: =AK25 | AN25: =AM25 | AO25: =AM25 | AP25: =AO25 | AQ25: =AP25 | AR25: =AQ25 | AS25: =AR25 | AT25: =AS25 | AU25: =AT25 | AW25: =AV25 | AX25: =AW25 | AY25: =AX25 | AZ25: =AY25 | BB25: =BA25 | BC25: =BA25 | BD25: =BA25 | BF25: =BE25 | BG25: =BF25 | BH25: =BG25 | BI25: =BH25 | BJ25: =BI25 | BM25: =BL25 | BN25: =BM25 | BO25: =BN25 | BQ25: =BP25 | BR25: =BQ25 | BS25: =BR25 | BT25: =BS25 | BV25: =BU25 | BX25: =BV25 | BY25: =BV25 | CA25: =BZ25 | CB25: =CA25 | CC25: =CB25 | CE25: =CD25 | CF25: =CE25 | CI25: =CG25 | CJ25: =CH25 | CK25: =CI25 | CM25: =CL25 | CN25: =CM25 | CP25: =CN25 | CR25: =CQ25 | CS25: =CR25 | CT25: =CS25 | CU25: =CT25 | CW25: =CV25 | CX25: =CW25 | CY25: =CX25 | CZ25: =CY25 | DA25: =CZ25 | DB25: =DA25 | DD25: =DC25
A26: {[][<]CCCCCCO[>][]} | B26: {[][>]OCCCCCC[<][]} | C26: Polyoxyhexamethylene | D26: Bicerano's Book | E26: Single Object | G26: =F26 | H26: =F26 | I26: =F26 | J26: =F26 | P26: =O26 | Q26: =O26 | R26: =O26 | S26: =O26 | T26: =O26 | U26: =O26 | W26: =V26 | X26: =V26 | Y26: =V26 | Z26: =V26 | AA26: =V26 | AB26: =V26 | AD26: =AC26 | AE26: =AC26 | AF26: =AC26 | AG26: =AC26 | AI26: =AH26 | AJ26: =AI26 | AK26: =AJ26 | AL26: =AK26 | AN26: =AM26 | AO26: =AM26 | AP26: =AO26 | AQ26: =AP26 | AR26: =AQ26 | AS26: =AR26 | AT26: =AS26 | AU26: =AT26 | AW26: =AV26 | AX26: =AW26 | AY26: =AX26 | AZ26: =AY26 | BB26: =BA26 | BC26: =BA26 | BD26: =BA26 | BF26: =BE26 | BG26: =BF26 | BH26: =BG26 | BI26: =BH26 | BJ26: =BI26 | BM26: =BL26 | BN26: =BM26 | BO26: =BN26 | BQ26: =BP26 | BR26: =BQ26 | BS26: =BR26 | BT26: =BS26 | BV26: =BU26 | BX26: =BV26 | BY26: =BV26 | CA26: =BZ26 | CB26: =CA26 | CC26: =CB26 | CE26: =CD26 | CF26: =CE26 | CI26: =CG26 | CJ26: =CH26 | CK26: =CI26 | CM26: =CL26 | CN26: =CM26 | CP26: =CN26 | CR26: =CQ26 | CS26: =CR26 | CT26: =CS26 | CU26: =CT26 | CW26: =CV26 | CX26: =CW26 | CY26: =CX26 | CZ26: =CY26 | DA26: =CZ26 | DB26: =DA26 | DD26: =DC26
A27: {[][<]OCCCCO[<],[>]C(=O)CCCCC(=O)[>][]} | B27: {[][>2]OCCCCO[<1],[>3]C(=O)CCCCC(=O)[<2],[>2]OCCCCO[<3],[>3]C(=O)CCCCC(=O)[<1][]} | C27: Poly(tetramethylene adipate) | D27: Bicerano's Book | E27: Single Object | G27: =F27 | H27: =F27 | I27: =F27 | J27: =F27 | P27: =O27 | Q27: =O27 | R27: =O27 | S27: =O27 | T27: =O27 | U27: =O27 | W27: =V27 | X27: =V27 | Y27: =V27 | Z27: =V27 | AA27: =V27 | AB27: =V27 | AD27: =AC27 | AE27: =AC27 | AF27: =AC27 | AG27: =AC27 | AI27: =AH27 | AJ27: =AI27 | AK27: =AJ27 | AL27: =AK27 | AN27: =AM27 | AO27: =AM27 | AP27: =AO27 | AQ27: =AP27 | AR27: =AQ27 | AS27: =AR27 | AT27: =AS27 | AU27: =AT27 | AW27: =AV27 | AX27: =AW27 | AY27: =AX27 | AZ27: =AY27 | BB27: =BA27 | BC27: =BA27 | BD27: =BA27 | BF27: =BE27 | BG27: =BF27 | BH27: =BG27 | BI27: =BH27 | BJ27: =BI27 | BM27: =BL27 | BN27: =BM27 | BO27: =BN27 | BQ27: =BP27 | BR27: =BQ27 | BS27: =BR27 | BT27: =BS27 | BV27: =BU27 | BX27: =BV27 | BY27: =BV27 | CA27: =BZ27 | CB27: =CA27 | CC27: =CB27 | CE27: =CD27 | CF27: =CE27 | CI27: =CG27 | CJ27: =CH27 | CK27: =CI27 | CM27: =CL27 | CN27: =CM27 | CP27: =CN27 | CR27: =CQ27 | CS27: =CR27 | CT27: =CS27 | CU27: =CT27 | CW27: =CV27 | CX27: =CW27 | CY27: =CX27 | CZ27: =CY27 | DA27: =CZ27 | DB27: =DA27 | DD27: =DC27
A28: {[][<]CCO[>][]} | B28: {[][>]OCC[<][]} | C28: Polyoxyethylene | D28: Bicerano's Book | E28: Single Object | F28: 1 | G28: =F28 | H28: =F28 | I28: =F28 | J28: =F28 | P28: =O28 | Q28: =O28 | R28: =O28 | S28: =O28 | T28: =O28 | U28: =O28 | W28: =V28 | X28: =V28 | Y28: =V28 | Z28: =V28 | AA28: =V28 | AB28: =V28 | AD28: =AC28 | AE28: =AC28 | AF28: =AC28 | AG28: =AC28 | AI28: =AH28 | AJ28: =AI28 | AK28: =AJ28 | AL28: =AK28 | AN28: =AM28 | AO28: =AM28 | AP28: =AO28 | AQ28: =AP28 | AR28: =AQ28 | AS28: =AR28 | AT28: =AS28 | AU28: =AT28 | AW28: =AV28 | AX28: =AW28 | AY28: =AX28 | AZ28: =AY28 | BB28: =BA28 | BC28: =BA28 | BD28: =BA28 | BF28: =BE28 | BG28: =BF28 | BH28: =BG28 | BI28: =BH28 | BJ28: =BI28 | BM28: =BL28 | BN28: =BM28 | BO28: =BN28 | BQ28: =BP28 | BR28: =BQ28 | BS28: =BR28 | BT28: =BS28 | BV28: =BU28 | BX28: =BV28 | BY28: =BV28 | CA28: =BZ28 | CB28: =CA28 | CC28: =CB28 | CE28: =CD28 | CF28: =CE28 | CI28: =CG28 | CJ28: =CH28 | CK28: =CI28 | CM28: =CL28 | CN28: =CM28 | CP28: =CN28 | CR28: =CQ28 | CS28: =CR28 | CT28: =CS28 | CU28: =CT28 | CW28: =CV28 | CX28: =CW28 | CY28: =CX28 | CZ28: =CY28 | DA28: =CZ28 | DB28: =DA28 | DD28: =DC28
A29: {[][<]CC(C)O[>],[<]C(C)CO[>][]} | B29: {[][>]OCC(C)[<],[>]OC(C)C[<][]} | C29: Poly(propylene oxide) | D29: Bicerano's Book | E29: Single Object | G29: =F29 | H29: =F29 | I29: =F29 | J29: =F29 | P29: =O29 | Q29: =O29 | R29: =O29 | S29: =O29 | T29: =O29 | U29: =O29 | W29: =V29 | X29: =V29 | Y29: =V29 | Z29: =V29 | AA29: =V29 | AB29: =V29 | AD29: =AC29 | AE29: =AC29 | AF29: =AC29 | AG29: =AC29 | AI29: =AH29 | AJ29: =AI29 | AK29: =AJ29 | AL29: =AK29 | AN29: =AM29 | AO29: =AM29 | AP29: =AO29 | AQ29: =AP29 | AR29: =AQ29 | AS29: =AR29 | AT29: =AS29 | AU29: =AT29 | AW29: =AV29 | AX29: =AW29 | AY29: =AX29 | AZ29: =AY29 | BB29: =BA29 | BC29: =BA29 | BD29: =BA29 | BF29: =BE29 | BG29: =BF29 | BH29: =BG29 | BI29: =BH29 | BJ29: =BI29 | BM29: =BL29 | BN29: =BM29 | BO29: =BN29 | BQ29: =BP29 | BR29: =BQ29 | BS29: =BR29 | BT29: =BS29 | BV29: =BU29 | BX29: =BV29 | BY29: =BV29 | CA29: =BZ29 | CB29: =CA29 | CC29: =CB29 | CE29: =CD29 | CF29: =CE29 | CI29: =CG29 | CJ29: =CH29 | CK29: =CI29 | CM29: =CL29 | CN29: =CM29 | CP29: =CN29 | CR29: =CQ29 | CS29: =CR29 | CT29: =CS29 | CU29: =CT29 | CW29: =CV29 | CX29: =CW29 | CY29: =CX29 | CZ29: =CY29 | DA29: =CZ29 | DB29: =DA29 | DD29: =DC29
A30: {[][$]CC(OCCCCC)[$][]} | B30: {[][>]CC(OCCCCC)[<],[>]C(OCCCCC)C[<][]} | C30: Poly(vinyl n-pentyl ether) | D30: Bicerano's Book | E30: Single Object | G30: =F30 | H30: =F30 | I30: =F30 | J30: =F30 | P30: =O30 | Q30: =O30 | R30: =O30 | S30: =O30 | T30: =O30 | U30: =O30 | W30: =V30 | X30: =V30 | Y30: =V30 | Z30: =V30 | AA30: =V30 | AB30: =V30 | AD30: =AC30 | AE30: =AC30 | AF30: =AC30 | AG30: =AC30 | AI30: =AH30 | AJ30: =AI30 | AK30: =AJ30 | AL30: =AK30 | AN30: =AM30 | AO30: =AM30 | AP30: =AO30 | AQ30: =AP30 | AR30: =AQ30 | AS30: =AR30 | AT30: =AS30 | AU30: =AT30 | AW30: =AV30 | AX30: =AW30 | AY30: =AX30 | AZ30: =AY30 | BB30: =BA30 | BC30: =BA30 | BD30: =BA30 | BF30: =BE30 | BG30: =BF30 | BH30: =BG30 | BI30: =BH30 | BJ30: =BI30 | BM30: =BL30 | BN30: =BM30 | BO30: =BN30 | BQ30: =BP30 | BR30: =BQ30 | BS30: =BR30 | BT30: =BS30 | BV30: =BU30 | BX30: =BV30 | BY30: =BV30 | CA30: =BZ30 | CB30: =CA30 | CC30: =CB30 | CE30: =CD30 | CF30: =CE30 | CI30: =CG30 | CJ30: =CH30 | CK30: =CI30 | CM30: =CL30 | CN30: =CM30 | CP30: =CN30 | CR30: =CQ30 | CS30: =CR30 | CT30: =CS30 | CU30: =CT30 | CW30: =CV30 | CX30: =CW30 | CY30: =CX30 | CZ30: =CY30 | DA30: =CZ30 | DB30: =DA30 | DD30: =DC30
A31: {[][$]CC(OCC(CC)CCCC)[$][]} | B31: {[][>]CC(OCC(CCCC)CC)[<],[>]C(OCC(CCCC)CC)C[<][]} | C31: Poly(vinyl 2-ethylhexyl ether) | D31: Bicerano's Book | E31: Single Object | G31: =F31 | H31: =F31 | I31: =F31 | J31: =F31 | P31: =O31 | Q31: =O31 | R31: =O31 | S31: =O31 | T31: =O31 | U31: =O31 | W31: =V31 | X31: =V31 | Y31: =V31 | Z31: =V31 | AA31: =V31 | AB31: =V31 | AD31: =AC31 | AE31: =AC31 | AF31: =AC31 | AG31: =AC31 | AI31: =AH31 | AJ31: =AI31 | AK31: =AJ31 | AL31: =AK31 | AN31: =AM31 | AO31: =AM31 | AP31: =AO31 | AQ31: =AP31 | AR31: =AQ31 | AS31: =AR31 | AT31: =AS31 | AU31: =AT31 | AW31: =AV31 | AX31: =AW31 | AY31: =AX31 | AZ31: =AY31 | BB31: =BA31 | BC31: =BA31 | BD31: =BA31 | BF31: =BE31 | BG31: =BF31 | BH31: =BG31 | BI31: =BH31 | BJ31: =BI31 | BM31: =BL31 | BN31: =BM31 | BO31: =BN31 | BQ31: =BP31 | BR31: =BQ31 | BS31: =BR31 | BT31: =BS31 | BV31: =BU31 | BX31: =BV31 | BY31: =BV31 | CA31: =BZ31 | CB31: =CA31 | CC31: =CB31 | CE31: =CD31 | CF31: =CE31 | CI31: =CG31 | CJ31: =CH31 | CK31: =CI31 | CM31: =CL31 | CN31: =CM31 | CP31: =CN31 | CR31: =CQ31 | CS31: =CR31 | CT31: =CS31 | CU31: =CT31 | CW31: =CV31 | CX31: =CW31 | CY31: =CX31 | CZ31: =CY31 | DA31: =CZ31 | DB31: =DA31 | DD31: =DC31
A32: {[][$]CC(C(=O)OCCCCCCCC)[$][]} | B32: {[][>]CC(C(OCCCCCCCC)=O)[<],[>]C(C(OCCCCCCCC)=O)C[<][]} | C32: Poly(n-octyl acrylate) | D32: Bicerano's Book | E32: Single Object | G32: =F32 | H32: =F32 | I32: =F32 | J32: =F32 | P32: =O32 | Q32: =O32 | R32: =O32 | S32: =O32 | T32: =O32 | U32: =O32 | W32: =V32 | X32: =V32 | Y32: =V32 | Z32: =V32 | AA32: =V32 | AB32: =V32 | AD32: =AC32 | AE32: =AC32 | AF32: =AC32 | AG32: =AC32 | AI32: =AH32 | AJ32: =AI32 | AK32: =AJ32 | AL32: =AK32 | AN32: =AM32 | AO32: =AM32 | AP32: =AO32 | AQ32: =AP32 | AR32: =AQ32 | AS32: =AR32 | AT32: =AS32 | AU32: =AT32 | AW32: =AV32 | AX32: =AW32 | AY32: =AX32 | AZ32: =AY32 | BB32: =BA32 | BC32: =BA32 | BD32: =BA32 | BF32: =BE32 | BG32: =BF32 | BH32: =BG32 | BI32: =BH32 | BJ32: =BI32 | BM32: =BL32 | BN32: =BM32 | BO32: =BN32 | BQ32: =BP32 | BR32: =BQ32 | BS32: =BR32 | BT32: =BS32 | BV32: =BU32 | BX32: =BV32 | BY32: =BV32 | CA32: =BZ32 | CB32: =CA32 | CC32: =CB32 | CE32: =CD32 | CF32: =CE32 | CI32: =CG32 | CJ32: =CH32 | CK32: =CI32 | CM32: =CL32 | CN32: =CM32 | CP32: =CN32 | CR32: =CQ32 | CS32: =CR32 | CT32: =CS32 | CU32: =CT32 | CW32: =CV32 | CX32: =CW32 | CY32: =CX32 | CZ32: =CY32 | DA32: =CZ32 | DB32: =DA32 | DD32: =DC32
A33: {[][$]CC(OCCCCCC)[$][]} | B33: {[][>]CC(OCCCCCC)[<],[>]C(OCCCCCC)C[<][]} | C33: Poly(vinyl n-hexyl ether) | D33: Bicerano's Book | E33: Single Object | G33: =F33 | H33: =F33 | I33: =F33 | J33: =F33 | P33: =O33 | Q33: =O33 | R33: =O33 | S33: =O33 | T33: =O33 | U33: =O33 | W33: =V33 | X33: =V33 | Y33: =V33 | Z33: =V33 | AA33: =V33 | AB33: =V33 | AD33: =AC33 | AE33: =AC33 | AF33: =AC33 | AG33: =AC33 | AI33: =AH33 | AJ33: =AI33 | AK33: =AJ33 | AL33: =AK33 | AN33: =AM33 | AO33: =AM33 | AP33: =AO33 | AQ33: =AP33 | AR33: =AQ33 | AS33: =AR33 | AT33: =AS33 | AU33: =AT33 | AW33: =AV33 | AX33: =AW33 | AY33: =AX33 | AZ33: =AY33 | BB33: =BA33 | BC33: =BA33 | BD33: =BA33 | BF33: =BE33 | BG33: =BF33 | BH33: =BG33 | BI33: =BH33 | BJ33: =BI33 | BM33: =BL33 | BN33: =BM33 | BO33: =BN33 | BQ33: =BP33 | BR33: =BQ33 | BS33: =BR33 | BT33: =BS33 | BV33: =BU33 | BX33: =BV33 | BY33: =BV33 | CA33: =BZ33 | CB33: =CA33 | CC33: =CB33 | CE33: =CD33 | CF33: =CE33 | CI33: =CG33 | CJ33: =CH33 | CK33: =CI33 | CM33: =CL33 | CN33: =CM33 | CP33: =CN33 | CR33: =CQ33 | CS33: =CR33 | CT33: =CS33 | CU33: =CT33 | CW33: =CV33 | CX33: =CW33 | CY33: =CX33 | CZ33: =CY33 | DA33: =CZ33 | DB33: =DA33 | DD33: =DC33
A34: {[][<]CC(OC)O[>],[<]C(OC)CO[>][]} | B34: {[][>]OCC(OC)[<],[>]OC(OC)C[<][]} | C34: Poly(3-methoxypropylene oxide) | D34: Bicerano's Book | E34: Single Object | G34: =F34 | H34: =F34 | I34: =F34 | J34: =F34 | P34: =O34 | Q34: =O34 | R34: =O34 | S34: =O34 | T34: =O34 | U34: =O34 | W34: =V34 | X34: =V34 | Y34: =V34 | Z34: =V34 | AA34: =V34 | AB34: =V34 | AD34: =AC34 | AE34: =AC34 | AF34: =AC34 | AG34: =AC34 | AI34: =AH34 | AJ34: =AI34 | AK34: =AJ34 | AL34: =AK34 | AN34: =AM34 | AO34: =AM34 | AP34: =AO34 | AQ34: =AP34 | AR34: =AQ34 | AS34: =AR34 | AT34: =AS34 | AU34: =AT34 | AW34: =AV34 | AX34: =AW34 | AY34: =AX34 | AZ34: =AY34 | BB34: =BA34 | BC34: =BA34 | BD34: =BA34 | BF34: =BE34 | BG34: =BF34 | BH34: =BG34 | BI34: =BH34 | BJ34: =BI34 | BM34: =BL34 | BN34: =BM34 | BO34: =BN34 | BQ34: =BP34 | BR34: =BQ34 | BS34: =BR34 | BT34: =BS34 | BV34: =BU34 | BX34: =BV34 | BY34: =BV34 | CA34: =BZ34 | CB34: =CA34 | CC34: =CB34 | CE34: =CD34 | CF34: =CE34 | CI34: =CG34 | CJ34: =CH34 | CK34: =CI34 | CM34: =CL34 | CN34: =CM34 | CP34: =CN34 | CR34: =CQ34 | CS34: =CR34 | CT34: =CS34 | CU34: =CT34 | CW34: =CV34 | CX34: =CW34 | CY34: =CX34 | CZ34: =CY34 | DA34: =CZ34 | DB34: =DA34 | DD34: =DC34
A35: {[][$]CC=CC(C)[$],[$]CC(C=CC)[$],[$]C(C)C(C=C)[$][]} | B35: {[][>]C(C)C(C=C)[<],[>]C(C=C)C(C)[<],[>]CC=CC(C)[<],[>]C(C)C=CC[<],[>]CC(C=CC)[<],[>]C(C=CC)C[<][]} | C35: Polypentadiene | D35: Bicerano's Book | E35: Single Object | G35: =F35 | H35: =F35 | I35: =F35 | J35: =F35 | P35: =O35 | Q35: =O35 | R35: =O35 | S35: =O35 | T35: =O35 | U35: =O35 | W35: =V35 | X35: =V35 | Y35: =V35 | Z35: =V35 | AA35: =V35 | AB35: =V35 | AD35: =AC35 | AE35: =AC35 | AF35: =AC35 | AG35: =AC35 | AI35: =AH35 | AJ35: =AI35 | AK35: =AJ35 | AL35: =AK35 | AN35: =AM35 | AO35: =AM35 | AP35: =AO35 | AQ35: =AP35 | AR35: =AQ35 | AS35: =AR35 | AT35: =AS35 | AU35: =AT35 | AW35: =AV35 | AX35: =AW35 | AY35: =AX35 | AZ35: =AY35 | BB35: =BA35 | BC35: =BA35 | BD35: =BA35 | BF35: =BE35 | BG35: =BF35 | BH35: =BG35 | BI35: =BH35 | BJ35: =BI35 | BM35: =BL35 | BN35: =BM35 | BO35: =BN35 | BQ35: =BP35 | BR35: =BQ35 | BS35: =BR35 | BT35: =BS35 | BV35: =BU35 | BX35: =BV35 | BY35: =BV35 | CA35: =BZ35 | CB35: =CA35 | CC35: =CB35 | CE35: =CD35 | CF35: =CE35 | CI35: =CG35 | CJ35: =CH35 | CK35: =CI35 | CM35: =CL35 | CN35: =CM35 | CP35: =CN35 | CR35: =CQ35 | CS35: =CR35 | CT35: =CS35 | CU35: =CT35 | CW35: =CV35 | CX35: =CW35 | CY35: =CX35 | CZ35: =CY35 | DA35: =CZ35 | DB35: =DA35 | DD35: =DC35
A36: {[][$]CC(C(=O)OCCCCCCC)[$][]} | B36: {[][>]CC(C(OCCCCCCC)=O)[<],[>]C(C(OCCCCCCC)=O)C[<][]} | C36: Poly(n-heptyl acrylate) | D36: Bicerano's Book | E36: Single Object | G36: =F36 | H36: =F36 | I36: =F36 | J36: =F36 | P36: =O36 | Q36: =O36 | R36: =O36 | S36: =O36 | T36: =O36 | U36: =O36 | W36: =V36 | X36: =V36 | Y36: =V36 | Z36: =V36 | AA36: =V36 | AB36: =V36 | AD36: =AC36 | AE36: =AC36 | AF36: =AC36 | AG36: =AC36 | AI36: =AH36 | AJ36: =AI36 | AK36: =AJ36 | AL36: =AK36 | AN36: =AM36 | AO36: =AM36 | AP36: =AO36 | AQ36: =AP36 | AR36: =AQ36 | AS36: =AR36 | AT36: =AS36 | AU36: =AT36 | AW36: =AV36 | AX36: =AW36 | AY36: =AX36 | AZ36: =AY36 | BB36: =BA36 | BC36: =BA36 | BD36: =BA36 | BF36: =BE36 | BG36: =BF36 | BH36: =BG36 | BI36: =BH36 | BJ36: =BI36 | BM36: =BL36 | BN36: =BM36 | BO36: =BN36 | BQ36: =BP36 | BR36: =BQ36 | BS36: =BR36 | BT36: =BS36 | BV36: =BU36 | BX36: =BV36 | BY36: =BV36 | CA36: =BZ36 | CB36: =CA36 | CC36: =CB36 | CE36: =CD36 | CF36: =CE36 | CI36: =CG36 | CJ36: =CH36 | CK36: =CI36 | CM36: =CL36 | CN36: =CM36 | CP36: =CN36 | CR36: =CQ36 | CS36: =CR36 | CT36: =CS36 | CU36: =CT36 | CW36: =CV36 | CX36: =CW36 | CY36: =CX36 | CZ36: =CY36 | DA36: =CZ36 | DB36: =DA36 | DD36: =DC36
A37: {[][<]OCCCCCC(=O)[>][]} | B37: {[][>]OCCCCCC(=O)[<][]} | C37: Poly(ε-caprolactone) | D37: Bicerano's Book | E37: Single Object | G37: =F37 | H37: =F37 | I37: =F37 | J37: =F37 | P37: =O37 | Q37: =O37 | R37: =O37 | S37: =O37 | T37: =O37 | U37: =O37 | W37: =V37 | X37: =V37 | Y37: =V37 | Z37: =V37 | AA37: =V37 | AB37: =V37 | AD37: =AC37 | AE37: =AC37 | AF37: =AC37 | AG37: =AC37 | AI37: =AH37 | AJ37: =AI37 | AK37: =AJ37 | AL37: =AK37 | AN37: =AM37 | AO37: =AM37 | AP37: =AO37 | AQ37: =AP37 | AR37: =AQ37 | AS37: =AR37 | AT37: =AS37 | AU37: =AT37 | AW37: =AV37 | AX37: =AW37 | AY37: =AX37 | AZ37: =AY37 | BB37: =BA37 | BC37: =BA37 | BD37: =BA37 | BF37: =BE37 | BG37: =BF37 | BH37: =BG37 | BI37: =BH37 | BJ37: =BI37 | BM37: =BL37 | BN37: =BM37 | BO37: =BN37 | BQ37: =BP37 | BR37: =BQ37 | BS37: =BR37 | BT37: =BS37 | BV37: =BU37 | BX37: =BV37 | BY37: =BV37 | CA37: =BZ37 | CB37: =CA37 | CC37: =CB37 | CE37: =CD37 | CF37: =CE37 | CI37: =CG37 | CJ37: =CH37 | CK37: =CI37 | CM37: =CL37 | CN37: =CM37 | CP37: =CN37 | CR37: =CQ37 | CS37: =CR37 | CT37: =CS37 | CU37: =CT37 | CW37: =CV37 | CX37: =CW37 | CY37: =CX37 | CZ37: =CY37 | DA37: =CZ37 | DB37: =DA37 | DD37: =DC37
A38: {[][$]CC(C(=O)OCCCCCCCCC)[$][]} | B38: {[][>]CC(C(OCCCCCCCCC)=O)[<],[>]C(C(OCCCCCCCCC)=O)C[<][]} | C38: Poly(n-nonyl acrylate) | D38: Bicerano's Book | E38: Single Object | G38: =F38 | H38: =F38 | I38: =F38 | J38: =F38 | P38: =O38 | Q38: =O38 | R38: =O38 | S38: =O38 | T38: =O38 | U38: =O38 | W38: =V38 | X38: =V38 | Y38: =V38 | Z38: =V38 | AA38: =V38 | AB38: =V38 | AD38: =AC38 | AE38: =AC38 | AF38: =AC38 | AG38: =AC38 | AI38: =AH38 | AJ38: =AI38 | AK38: =AJ38 | AL38: =AK38 | AN38: =AM38 | AO38: =AM38 | AP38: =AO38 | AQ38: =AP38 | AR38: =AQ38 | AS38: =AR38 | AT38: =AS38 | AU38: =AT38 | AW38: =AV38 | AX38: =AW38 | AY38: =AX38 | AZ38: =AY38 | BB38: =BA38 | BC38: =BA38 | BD38: =BA38 | BF38: =BE38 | BG38: =BF38 | BH38: =BG38 | BI38: =BH38 | BJ38: =BI38 | BM38: =BL38 | BN38: =BM38 | BO38: =BN38 | BQ38: =BP38 | BR38: =BQ38 | BS38: =BR38 | BT38: =BS38 | BV38: =BU38 | BX38: =BV38 | BY38: =BV38 | CA38: =BZ38 | CB38: =CA38 | CC38: =CB38 | CE38: =CD38 | CF38: =CE38 | CI38: =CG38 | CJ38: =CH38 | CK38: =CI38 | CM38: =CL38 | CN38: =CM38 | CP38: =CN38 | CR38: =CQ38 | CS38: =CR38 | CT38: =CS38 | CU38: =CT38 | CW38: =CV38 | CX38: =CW38 | CY38: =CX38 | CZ38: =CY38 | DA38: =CZ38 | DB38: =DA38 | DD38: =DC38
A39: {[][$]CC(C(=O)OCCCCCC)[$][]} | B39: {[][>]CC(C(OCCCCCC)=O)[<],[>]C(C(OCCCCCC)=O)C[<][]} | C39: Poly(n-hexyl acrylate) | D39: Bicerano's Book | E39: Single Object | G39: =F39 | H39: =F39 | I39: =F39 | J39: =F39 | P39: =O39 | Q39: =O39 | R39: =O39 | S39: =O39 | T39: =O39 | U39: =O39 | W39: =V39 | X39: =V39 | Y39: =V39 | Z39: =V39 | AA39: =V39 | AB39: =V39 | AD39: =AC39 | AE39: =AC39 | AF39: =AC39 | AG39: =AC39 | AI39: =AH39 | AJ39: =AI39 | AK39: =AJ39 | AL39: =AK39 | AN39: =AM39 | AO39: =AM39 | AP39: =AO39 | AQ39: =AP39 | AR39: =AQ39 | AS39: =AR39 | AT39: =AS39 | AU39: =AT39 | AW39: =AV39 | AX39: =AW39 | AY39: =AX39 | AZ39: =AY39 | BB39: =BA39 | BC39: =BA39 | BD39: =BA39 | BF39: =BE39 | BG39: =BF39 | BH39: =BG39 | BI39: =BH39 | BJ39: =BI39 | BM39: =BL39 | BN39: =BM39 | BO39: =BN39 | BQ39: =BP39 | BR39: =BQ39 | BS39: =BR39 | BT39: =BS39 | BV39: =BU39 | BX39: =BV39 | BY39: =BV39 | CA39: =BZ39 | CB39: =CA39 | CC39: =CB39 | CE39: =CD39 | CF39: =CE39 | CI39: =CG39 | CJ39: =CH39 | CK39: =CI39 | CM39: =CL39 | CN39: =CM39 | CP39: =CN39 | CR39: =CQ39 | CS39: =CR39 | CT39: =CS39 | CU39: =CT39 | CW39: =CV39 | CX39: =CW39 | CY39: =CX39 | CZ39: =CY39 | DA39: =CZ39 | DB39: =DA39 | DD39: =DC39
A40: {[][<]OCCCCCCCCCCO[<],[>]C(=O)CCCCC(=O)[>][]} | B40: {[][>2]C(=O)CCCCC(=O)[<1],[>3]OCCCCCCCCCCO[<2],[>2]C(=O)CCCCC(=O)[<3],[>3]OCCCCCCCCCCO[<1][]} | C40: Poly(decamethylene adipate) | D40: Bicerano's Book | E40: Single Object | G40: =F40 | H40: =F40 | I40: =F40 | J40: =F40 | P40: =O40 | Q40: =O40 | R40: =O40 | S40: =O40 | T40: =O40 | U40: =O40 | W40: =V40 | X40: =V40 | Y40: =V40 | Z40: =V40 | AA40: =V40 | AB40: =V40 | AD40: =AC40 | AE40: =AC40 | AF40: =AC40 | AG40: =AC40 | AI40: =AH40 | AJ40: =AI40 | AK40: =AJ40 | AL40: =AK40 | AN40: =AM40 | AO40: =AM40 | AP40: =AO40 | AQ40: =AP40 | AR40: =AQ40 | AS40: =AR40 | AT40: =AS40 | AU40: =AT40 | AW40: =AV40 | AX40: =AW40 | AY40: =AX40 | AZ40: =AY40 | BB40: =BA40 | BC40: =BA40 | BD40: =BA40 | BF40: =BE40 | BG40: =BF40 | BH40: =BG40 | BI40: =BH40 | BJ40: =BI40 | BM40: =BL40 | BN40: =BM40 | BO40: =BN40 | BQ40: =BP40 | BR40: =BQ40 | BS40: =BR40 | BT40: =BS40 | BV40: =BU40 | BX40: =BV40 | BY40: =BV40 | CA40: =BZ40 | CB40: =CA40 | CC40: =CB40 | CE40: =CD40 | CF40: =CE40 | CI40: =CG40 | CJ40: =CH40 | CK40: =CI40 | CM40: =CL40 | CN40: =CM40 | CP40: =CN40 | CR40: =CQ40 | CS40: =CR40 | CT40: =CS40 | CU40: =CT40 | CW40: =CV40 | CX40: =CW40 | CY40: =CX40 | CZ40: =CY40 | DA40: =CZ40 | DB40: =DA40 | DD40: =DC40
...

Sheet Block
A1: ='Single Object'!A1 | B1: Single Object Canonicalized | C1: ='Single Object'!C1 | D1: ='Single Object'!D1 | E1: ='Single Object'!E1 | F1: {[][$]CC(c1ccccc1)[$][$]}{[>][<][Si](C)(C)O[>][]} | G1: {[][$]CC([$])c1ccccc1[$]}{[>][<][Si](C)(C)O[>][]} | H1: {[][<][Si](C)(C)O[>][>]}{[$][$]CC(c1ccccc1)[$][]} | I1: {[][$]CC(c5ccccc5)[$][$]}{[>][<][Si](C)(C)O[>][]} | J1: COCCOCCO{[>][<]CCO[>][<]}{[>][<]C(CC)CO[>][<]}[H] | K1: {[][<]CCO[>];[>]OCCOCCOC[<]}{[>][<]C(CC)CO[>][<]}[H] | L1: COCCOC{[>][<]COC[>][<]}CO{[>][<]C(CC)CO[>][<]}[H] | M1: COCCO{[>][<]CCO[>][<]}CCO{[>][<]C(CC)CO[>][<]}[H] | N1: COCCO{[>][<]CCO[>],[<]CCO[>2],[<2]C(CC)CO[>2][<2]}[H] | O1: COCCO{[>][<]CCO[>2],[<]CCO[>],[<2]C(CC)CO[>2][<2]}[H] | P1: {[][<]CCO[>2],[<]CCO[>],[<2]C(CC)CO[>2];[>]OCCOC[<2]}[H] | Q1: [H]{[>][<]OCC(CC)[>][<]}{[>][<]OCC[>][<]}OCCOCCOC | R1: [H]{[>][>]CC(C)OC(=O)O[<][<]}OCC{[$][$]CC(c1ccccc1)[$][$]}C(C)CC | S1: CCC(C){[$][$]CC(c1ccccc1)[$][$]}CCO{[>][<]CC(C)OC(=O)O[>][<]} | T1: [H]{[>][>]CC(C)OC(=O)O[<];[<]OCC{[$][$]CC(c1ccccc1)[$][$]}C(C)CC[]} | U1: {[][<]OCC[>][<]}{[<][>]OC(C)C[<][>]}{[>][<]OCC[>][]} | V1: {[][<]OCC[>][<]}{[<][>]OC(C)C[<][>]}{[>][<]OCC[>][<]} | W1: {[][<]CCO[>][<]}{[>][<]CC(C)O[>][<]}{[>][<]CCO[>][]} | X1: CCC(C){[$][$]CC(c1ccccc1)[$][$]}{[$][$]C\C=C(C)/C[$],[$]C\C=C(C)\C[$],[$]CC(C(C)=C)[$],[$]CC(C)(C=C)[$][$]}{[$][$]CC(c1ccccc1)[$][$]}{[>][<]CCO[>][<]}[H] | Y1: CCC(C){[$][$]CC(c1ccccc1)[$][$]}{[$][$]C\C=C(C)\C[$],[$]C\C=C(C)/C[$],[$]CC(C(C)=C)[$],[$]CC(C)(C=C)[$][$]}{[$][$]CC(c1ccccc1)[$][$]}{[>][<]CCO[>][<]}[H] | Z1: CCC(C){[$][$]CC(c1ccccc1)[$][$]}{[$][$]C\C=C(C)/C[$],[$]C\C=C(C)\C[$],[$]CC(C(C)=C)[$],[$]CC(C)(C=C)[$][$]}{[$][$]CC(c1ccccc1)[$][$]}{[>][<]C[>2],[<2]CO[>][<]}[H] | AA1: {[][$]CC(C1CCCCC1)[$][$]}{[$][$]CC[<2],[>2]C(C)C[$],[$]CC(C(C)C)[$],[$]CC(C)(CC)[$][$]}{[$][$]CC(C1CCCCC1)[$][$]}{[$][$]CCC(C)C[$],[$]CC(C(C)C)[$],[$]CC(C)(CC)[$][$]}{[$][$]CC(C1CCCCC1)[$][$]}{[$][$]CCC(C)C[$],[$]CC(C(C)C)[$],[$]CC(C)(CC)[$][$]}{[$][$]CC(C1CCCCC1)[$][$]}{[$][$]CCC(C)C[$],[$]CC(C(C)C)[$],[$]CC(C)(CC)[$][$]}{[$][$]CC(C1CCCCC1)[$][$]}{[$][$]CCC(C)C[$],[$]CC(C(C)C)[$],[$]CC(C)(CC)[$][$]}{[$][$]CC(C1CCCCC1)[$][]}
F2: Original | G2: change SMILES | H2: flip blocks | I2: change SMILES ring ID | J2: block with initiator | K2: mixed implicit explicit representation | L2: frame shift | M2: frame shift | N2: conversion to single object | O2: rearrangement of RU | P2: implicit/explicit representation | Q2: flipped | R2: block with initiator and linker | S2: flip | T2: implicit/explicit representation | U2: pluronic triblock | V2: no match | W2: flip | X2: SISO tetrablock | Y2: RU rearrangement | Z2: RU split | AA2: split
E3: # of Matches | F3: =COUNTIF(F5:F1000, 1) | G3: =COUNTIF(G5:G1000, 1) | H3: =COUNTIF(H5:H1000, 1) | I3: =COUNTIF(I5:I1000, 1) | J3: =COUNTIF(J5:J1000, 1) | K3: =COUNTIF(K5:K1000, 1) | L3: =COUNTIF(L5:L1000, 1) | M3: =COUNTIF(M5:M1000, 1) | ... AA3: =COUNTIF(AA5:AA1000, 1)
E4: ='Single Object'!E4 | F4: block with no end group | J4: block with initiator | R4: block with initiator and linker | U4: pluronic triblock | X4: SISO tetrablock | AA4: undecablock split
A5: ='Single Object'!A5 | B5: {[][<1][Si](CC)(CC)O[>1][]} | C5: ='Single Object'!C5 | D5: ='Single Object'!D5 | E5: ='Single Object'!E5 | G5: =F5 | H5: =G5 | I5: =H5 | K5: =J5 | L5: =K5 | M5: =L5 | N5: =M5 | O5: =N5 | P5: =O5 | Q5: =P5 | S5: =R5 | T5: =S5 | W5: =U5 | Y5: =X5 | Z5: =Y5
A6: ='Single Object'!A6 | B6: {[][<1][Si](C)(C)O[>1][]} | C6: ='Single Object'!C6 | D6: ='Single Object'!D6 | E6: ='Single Object'!E6 | G6: =F6 | H6: =G6 | I6: =H6 | K6: =J6 | L6: =K6 | M6: =L6 | N6: =M6 | O6: =N6 | P6: =O6 | Q6: =P6 | S6: =R6 | T6: =S6 | W6: =U6 | Y6: =X6 | Z6: =Y6
A7: ='Single Object'!A7 | B7: {[][<1]CC=CC[>1][]} | C7: ='Single Object'!C7 | D7: ='Single Object'!D7 | E7: ='Single Object'!E7 | G7: =F7 | H7: =G7 | I7: =H7 | K7: =J7 | L7: =K7 | M7: =L7 | N7: =M7 | O7: =N7 | P7: =O7 | Q7: =P7 | S7: =R7 | T7: =S7 | W7: =U7 | Y7: =X7 | Z7: =Y7
A8: ='Single Object'!A8 | B8: {[][<1][Si](C)(C)C[>1][]} | C8: ='Single Object'!C8 | D8: ='Single Object'!D8 | E8: ='Single Object'!E8 | G8: =F8 | H8: =G8 | I8: =H8 | K8: =J8 | L8: =K8 | M8: =L8 | N8: =M8 | O8: =N8 | P8: =O8 | Q8: =P8 | S8: =R8 | T8: =S8 | W8: =U8 | Y8: =X8 | Z8: =Y8
A9: ='Single Object'!A9 | B9: {[][<1][Si](C)(c(cc1)ccc1)O[>1][]} | C9: ='Single Object'!C9 | D9: ='Single Object'!D9 | E9: ='Single Object'!E9 | G9: =F9 | H9: =G9 | I9: =H9 | K9: =J9 | L9: =K9 | M9: =L9 | N9: =M9 | O9: =N9 | P9: =O9 | Q9: =P9 | S9: =R9 | T9: =S9 | W9: =U9 | Y9: =X9 | Z9: =Y9
A10: ='Single Object'!A10 | B10: {[][<1]O[>2],[<2]C(COCCCCCC)C[>1],[<2]CC(COCCCCCC)[>1][]} | C10: ='Single Object'!C10 | D10: ='Single Object'!D10 | E10: ='Single Object'!E10 | G10: =F10 | H10: =G10 | I10: =H10 | K10: =J10 | L10: =K10 | M10: =L10 | N10: =M10 | O10: =N10 | P10: =O10 | Q10: =P10 | S10: =R10 | T10: =S10 | W10: =U10 | Y10: =X10 | Z10: =Y10
A11: ='Single Object'!A11 | B11: {[][<1]OCCCC[>1][]} | C11: ='Single Object'!C11 | D11: ='Single Object'!D11 | E11: ='Single Object'!E11 | G11: =F11 | H11: =G11 | I11: =H11 | K11: =J11 | L11: =K11 | M11: =L11 | N11: =M11 | O11: =N11 | P11: =O11 | Q11: =P11 | S11: =R11 | T11: =S11 | W11: =U11 | Y11: =X11 | Z11: =Y11
A12: ='Single Object'!A12 | B12: {[][<1][Si](C)(C)N[>1][]} | C12: ='Single Object'!C12 | D12: ='Single Object'!D12 | E12: ='Single Object'!E12 | G12: =F12 | H12: =G12 | I12: =H12 | K12: =J12 | L12: =K12 | M12: =L12 | N12: =M12 | O12: =N12 | P12: =O12 | Q12: =P12 | S12: =R12 | T12: =S12 | W12: =U12 | Y12: =X12 | Z12: =Y12
A13: ='Single Object'!A13 | B13: {[][<1]C[>2],[<2]C(CCCC)=C[>3],[<2]C=C(CCCC)[>3],[<3]C[>1][]} | C13: ='Single Object'!C13 | D13: ='Single Object'!D13 | E13: ='Single Object'!E13 | G13: =F13 | H13: =G13 | I13: =H13 | K13: =J13 | L13: =K13 | M13: =L13 | N13: =M13 | O13: =N13 | P13: =O13 | Q13: =P13 | S13: =R13 | T13: =S13 | W13: =U13 | Y13: =X13 | Z13: =Y13
A14: ='Single Object'!A14 | B14: {[][$1]C(OCCCCCCCC)C[$1][]} | C14: ='Single Object'!C14 | D14: ='Single Object'!D14 | E14: ='Single Object'!E14 | G14: =F14 | H14: =G14 | I14: =H14 | K14: =J14 | L14: =K14 | M14: =L14 | N14: =M14 | O14: =N14 | P14: =O14 | Q14: =P14 | S14: =R14 | T14: =S14 | W14: =U14 | Y14: =X14 | Z14: =Y14
A15: ='Single Object'!A15 | B15: {[][<1]O[>2],[<2]C(COCCCC)C[>1],[<2]CC(COCCCC)[>1][]} | C15: ='Single Object'!C15 | D15: ='Single Object'!D15 | E15: ='Single Object'!E15 | G15: =F15 | H15: =G15 | I15: =H15 | K15: =J15 | L15: =K15 | M15: =L15 | N15: =M15 | O15: =N15 | P15: =O15 | Q15: =P15 | S15: =R15 | T15: =S15 | W15: =U15 | Y15: =X15 | Z15: =Y15
A16: ='Single Object'!A16 | B16: {[][<1]CC[>1][]} | C16: ='Single Object'!C16 | D16: ='Single Object'!D16 | E16: ='Single Object'!E16 | G16: =F16 | H16: =G16 | I16: =H16 | K16: =J16 | L16: =K16 | M16: =L16 | N16: =M16 | O16: =N16 | P16: =O16 | Q16: =P16 | S16: =R16 | T16: =S16 | W16: =U16 | Y16: =X16 | Z16: =Y16
... A310: ='Single Object'!A310 | B310: {[][<1]c(cc1)ccc1C(=O)c(cc1)ccc1[>2],[<2]n(c(c1cc2c3=O)=O)c(=O)c1cc2c(=O)n3[>1][]} | C310: ='Single Object'!C310 | D310: ='Single Object'!D310 | E310: ='Single Object'!E310 | G310: =F310 | H310: =G310 | I310: =H310 | K310: =J310 | L310: =K310 | M310: =L310 | N310: =M310 | O310: =N310 | P310: =O310 | Q310: =P310 | S310: =R310 | T310: =S310 | W310: =U310 | Y310: =X310 | Z310: =Y310
A311: ='Single Object'!A311 | B311: {[][<1]O,[<2]CCO[>2],[>3][]} | C311: Beyond this point, naming becomes complicated, so let's use BigSMILES! | D311: ='Single Object'!D311 | E311: ='Single Object'!E311 | G311: =F311 | H311: =G311 | I311: =H311 | K311: =J311 | L311: =K311 | M311: =L311 | N311: =M311 | O311: =N311 | P311: =O311 | Q311: =P311 | S311: =R311 | T311: =S311 | W311: =U311 | Y311: =X311 | Z311: =Y311
A312: ='Single Object'!A312 | B312: {[][<1]O,[<2]CC[>3],[>4]O,[<3]O[>2][]} | D312: ='Single Object'!D312 | E312: ='Single Object'!E312 | G312: =F312 | H312: =G312 | I312: =H312 | K312: =J312 | L312: =K312 | M312: =L312 | N312: =M312 | O312: =N312 | P312: =O312 | Q312: =P312 | S312: =R312 | T312: =S312 | W312: =U312 | Y312: =X312 | Z312: =Y312
A313: ='Single Object'!A313 | B313: {[][<1]C,[<2]O[>3],[>4]C(C=C)=O,[<3]CC[>2][]} | D313: ='Single Object'!D313 | E313: ='Single Object'!E313 | G313: =F313 | H313: =G313 | I313: =H313 | K313: =J313 | L313: =K313 | M313: =L313 | N313: =M313 | O313: =N313 | P313: =O313 | Q313: =P313 | S313: =R313 | T313: =S313 | W313: =U313 | Y313: =X313 | Z313: =Y313
